Workbook

Sheet RECETAS
A1: Producto elaborado | B1: Insumo | C1: cantidad x unidad | D1: Costos | E1: Costo Total | F1: CMV | G1: Porcentaje | H1: Rentabilidad | I1: Markup | J1: Utilidad Bruta
A2: CHEESE BACON | B2: Blend de carne | C2: 220 | D2: =IFERROR(VLOOKUP(B2, FINANCIERO!A:D, 4, FALSE), "") -> 12.925 | E2: =C2*D2 -> 2843.5 | G2: =IF(F2=0, "", E2 / F2)
A3: CHEESE BACON | B3: cheedar feteado Milkaut | C3: 3 | D3: =IFERROR(VLOOKUP(B3, FINANCIERO!A:D, 4, FALSE), "") -> 225.53993 | E3: =C3*D3 -> 676.61979 | G3: =IF(F3=0, "", E3 / F3)
A4: CHEESE BACON | B4: Pan TBB | C4: 1 | D4: =IFERROR(VLOOKUP(B4, FINANCIERO!A:D, 4, FALSE), "") -> 648 | E4: =C4*D4 -> 648 | G4: =IF(F4=0, "", E4 / F4)
A5: CHEESE BACON | B5: Bacon | C5: 15 | D5: =IFERROR(VLOOKUP(B5, FINANCIERO!A:D, 4, FALSE), "") -> 5.63326 | E5: =C5*D5 -> 84.4989 | G5: =IF(F5=0, "", E5 / F5)
A6: CHEESE BACON | B6: Papas bastón SIMPLOT Extra Crunch | C6: 193 | D6: =IFERROR(VLOOKUP(B6, FINANCIERO!A:D, 4, FALSE), "") -> 3.4688413 | E6: =C6*D6 -> 669.48638 | G6: =IF(F6=0, "", E6 / F6)
A7: CHEESE BACON | B7: Parafinado Zoso LOTTA Burgers | C7: 1 | D7: =IFERROR(VLOOKUP(B7, FINANCIERO!A:D, 4, FALSE), "") -> 66.987179 | E7: =C7*D7 -> 66.987179 | G7: =IF(F7=0, "", E7 / F7)
A8: CHEESE BACON | B8: Sobre de papas fritas LOTTA | C8: 1 | D8: =IFERROR(VLOOKUP(B8, FINANCIERO!A:D, 4, FALSE), "") -> 35.909091 | E8: =C8*D8 -> 35.909091 | G8: =IF(F8=0, "", E8 / F8)
A9: CHEESE BACON | B9: Dips con tapa | C9: 1 | D9: =IFERROR(VLOOKUP(B9, FINANCIERO!A:D, 4, FALSE), "") -> 103.404 | E9: =C9*D9 -> 103.404 | G9: =IF(F9=0, "", E9 / F9)
A10: CHEESE BACON | B10: Salsa de Dips | C10: 1 | D10: =IFERROR(VLOOKUP(B10, FINANCIERO!A:D, 4, FALSE), "") -> 5.37514 | E10: =C10*D10 -> 5.37514 | G10: =IF(F10=0, "", E10 / F10)
A11: CHEESE BACON | B11: Servilletas | C11: 2 | D11: =IFERROR(VLOOKUP(B11, FINANCIERO!A:D, 4, FALSE), "") -> 24.625 | E11: =C11*D11 -> 49.25 | G11: =IF(F11=0, "", E11 / F11)
D12: =IFERROR(VLOOKUP(B12, FINANCIERO!A:D, 4, FALSE), "") | E12: =SUM(E2:E11) -> 5183.0305 | F12: 13900 | G12: =IF(F12=0, "", E12 / F12) -> 0.37287989 | H12: =100%-G12 -> 0.62712011 | I12: =(F12-E12)/E12*100 -> 168.18287 | J12: =F12-E12 -> 8716.9695
A13: BALDE DE MINI BURGERS | B13: Blend de carne | C13: 210 | D13: =IFERROR(VLOOKUP(B13, FINANCIERO!A:D, 4, FALSE), "") -> 12.925 | E13: =C13*D13 -> 2714.25 | G13: =IF(F13=0, "", E13 / F13)
A14: BALDE DE MINI BURGERS | B14: Pan chiquito 40 gr | C14: 6 | D14: =IFERROR(VLOOKUP(B14, FINANCIERO!A:D, 4, FALSE), "") -> 250 | E14: =C14*D14 -> 1500 | G14: =IF(F14=0, "", E14 / F14)
A15: BALDE DE MINI BURGERS | B15: Cheedar feteado Milkaut | C15: 3 | D15: =IFERROR(VLOOKUP(B15, FINANCIERO!A:D, 4, FALSE), "") -> 225.53993 | E15: =C15*D15 -> 676.61979 | G15: =IF(F15=0, "", E15 / F15)
A16: BALDE DE MINI BURGERS | B16: Cheddar liquido | C16: 70 | D16: =IFERROR(VLOOKUP(B16, FINANCIERO!A:D, 4, FALSE), "") -> 7.2801429 | E16: =C16*D16 -> 509.61 | G16: =IF(F16=0, "", E16 / F16)
A17: BALDE DE MINI BURGERS | B17: Tacita polipapel | C17: 1 | D17: =IFERROR(VLOOKUP(B17, FINANCIERO!A:D, 4, FALSE), "") -> 250 | E17: =C17*D17 -> 250 | G17: =IF(F17=0, "", E17 / F17)
A18: BALDE DE MINI BURGERS | B18: Balde de polipapel | C18: 1 | D18: =IFERROR(VLOOKUP(B18, FINANCIERO!A:D, 4, FALSE), "") -> 250 | E18: =C18*D18 -> 250 | G18: =IF(F18=0, "", E18 / F18)
D19: =IFERROR(VLOOKUP(B19, FINANCIERO!A:D, 4, FALSE), "") | E19: =SUM(E13:E18) -> 5900.4798 | F19: 15000 | G19: =IF(F19=0, "", E19 / F19) -> 0.39336532 | H19: =100%-G19 -> 0.60663468 | I19: =(F19-E19)/E19*100 -> 154.21662 | J19: =F19-E19 -> 9099.5202
A20: CHEESE BACON (SIMPLE) | B20: Blend de carne | C20: 110 | D20: =IFERROR(VLOOKUP(B20, FINANCIERO!A:D, 4, FALSE), "") -> 12.925 | E20: =C20*D20 -> 1421.75 | G20: =IF(F20=0, "", E20 / F20)
A21: CHEESE BACON (SIMPLE) | B21: cheedar feteado Milkaut | C21: 2 | D21: =IFERROR(VLOOKUP(B21, FINANCIERO!A:D, 4, FALSE), "") -> 225.53993 | E21: =C21*D21 -> 451.07986 | G21: =IF(F21=0, "", E21 / F21)
A22: CHEESE BACON (SIMPLE) | B22: Pan TBB | C22: 1 | D22: =IFERROR(VLOOKUP(B22, FINANCIERO!A:D, 4, FALSE), "") -> 648 | E22: =C22*D22 -> 648 | G22: =IF(F22=0, "", E22 / F22)
A23: CHEESE BACON (SIMPLE) | B23: Bacon | C23: 15 | D23: =IFERROR(VLOOKUP(B23, FINANCIERO!A:D, 4, FALSE), "") -> 5.63326 | E23: =C23*D23 -> 84.4989 | G23: =IF(F23=0, "", E23 / F23)
A24: CHEESE BACON (SIMPLE) | B24: Papas bastón SIMPLOT Extra Crunch | C24: 193 | D24: =IFERROR(VLOOKUP(B24, FINANCIERO!A:D, 4, FALSE), "") -> 3.4688413 | E24: =C24*D24 -> 669.48638 | G24: =IF(F24=0, "", E24 / F24)
A25: CHEESE BACON (SIMPLE) | B25: Parafinado Zoso LOTTA Burgers | C25: 1 | D25: =IFERROR(VLOOKUP(B25, FINANCIERO!A:D, 4, FALSE), "") -> 66.987179 | E25: =C25*D25 -> 66.987179 | G25: =IF(F25=0, "", E25 / F25)
A26: CHEESE BACON (SIMPLE) | B26: Sobre de papas fritas LOTTA | C26: 1 | D26: =IFERROR(VLOOKUP(B26, FINANCIERO!A:D, 4, FALSE), "") -> 35.909091 | E26: =C26*D26 -> 35.909091 | G26: =IF(F26=0, "", E26 / F26)
A27: CHEESE BACON (SIMPLE) | B27: Dips con tapa | C27: 1 | D27: =IFERROR(VLOOKUP(B27, FINANCIERO!A:D, 4, FALSE), "") -> 103.404 | E27: =C27*D27 -> 103.404 | G27: =IF(F27=0, "", E27 / F27)
A28: CHEESE BACON (SIMPLE) | B28: Salsa de Dips | C28: 1 | D28: =IFERROR(VLOOKUP(B28, FINANCIERO!A:D, 4, FALSE), "") -> 5.37514 | E28: =C28*D28 -> 5.37514 | G28: =IF(F28=0, "", E28 / F28)
A29: CHEESE BACON (SIMPLE) | B29: Servilletas | C29: 2 | D29: =IFERROR(VLOOKUP(B29, FINANCIERO!A:D, 4, FALSE), "") -> 24.625 | E29: =C29*D29 -> 49.25 | G29: =IF(F29=0, "", E29 / F29)
D30: =IFERROR(VLOOKUP(B30, FINANCIERO!A:D, 4, FALSE), "") | E30: =SUM(E20:E29) -> 3535.7405 | F30: 11000 | G30: =IF(F30=0, "", E30 / F30) -> 0.32143096 | H30: =100%-G30 -> 0.67856904 | I30: =(F30-E30)/E30*100 -> 211.1088 | J30: =F30-E30 -> 7464.2595
A31: CHEESE BURGER | B31: Blend de carne | C31: 220 | D31: =IFERROR(VLOOKUP(B31, FINANCIERO!A:D, 4, FALSE), "") -> 12.925 | E31: =C31*D31 -> 2843.5 | G31: =IF(F31=0, "", E31 / F31)
A32: CHEESE BURGER | B32: cheedar feteado Milkaut | C32: 3 | D32: =IFERROR(VLOOKUP(B32, FINANCIERO!A:D, 4, FALSE), "") -> 225.53993 | E32: =C32*D32 -> 676.61979 | G32: =IF(F32=0, "", E32 / F32)
A33: CHEESE BURGER | B33: Pan TBB | C33: 1 | D33: =IFERROR(VLOOKUP(B33, FINANCIERO!A:D, 4, FALSE), "") -> 648 | E33: =C33*D33 -> 648 | G33: =IF(F33=0, "", E33 / F33)
A34: CHEESE BURGER | B34: Papas bastón SIMPLOT Extra Crunch | C34: 193 | D34: =IFERROR(VLOOKUP(B34, FINANCIERO!A:D, 4, FALSE), "") -> 3.4688413 | E34: =C34*D34 -> 669.48638 | G34: =IF(F34=0, "", E34 / F34)
A35: CHEESE BURGER | B35: Parafinado Zoso LOTTA Burgers | C35: 1 | D35: =IFERROR(VLOOKUP(B35, FINANCIERO!A:D, 4, FALSE), "") -> 66.987179 | E35: =C35*D35 -> 66.987179 | G35: =IF(F35=0, "", E35 / F35)
A36: CHEESE BURGER | B36: Sobre de papas fritas LOTTA | C36: 1 | D36: =IFERROR(VLOOKUP(B36, FINANCIERO!A:D, 4, FALSE), "") -> 35.909091 | E36: =C36*D36 -> 35.909091 | G36: =IF(F36=0, "", E36 / F36)
A37: CHEESE BURGER | B37: Dips con tapa | C37: 1 | D37: =IFERROR(VLOOKUP(B37, FINANCIERO!A:D, 4, FALSE), "") -> 103.404 | E37: =C37*D37 -> 103.404 | G37: =IF(F37=0, "", E37 / F37)
A38: CHEESE BURGER | B38: Salsa de Dips | C38: 1 | D38: =IFERROR(VLOOKUP(B38, FINANCIERO!A:D, 4, FALSE), "") -> 5.37514 | E38: =C38*D38 -> 5.37514 | G38: =IF(F38=0, "", E38 / F38)
A39: CHEESE BURGER | B39: Servilletas | C39: 1 | D39: =IFERROR(VLOOKUP(B39, FINANCIERO!A:D, 4, FALSE), "") -> 24.625 | E39: =C39*D39 -> 24.625 | G39: =IF(F39=0, "", E39 / F39)
D40: =IFERROR(VLOOKUP(B40, FINANCIERO!A:D, 4, FALSE), "") | E40: =SUM(E31:E39) -> 5073.9066 | F40: 9000 | G40: =IF(F40=0, "", E40 / F40) -> 0.5637674 | H40: =100%-G40 -> 0.4362326 | I40: =(F40-E40)/E40*100 -> 77.378118 | J40: =F40-E40 -> 3926.0934
...

Sheet FINANCIERO
A2: Materia Prima | B2: Costo x bulto | C2: Unidad x bulto | D2: Costo unitario | E2: CHECK | F2: Actualización
A3: Blend de carne | B3: =(B39*0.5)+(B37*0.25)+(B38*0.25) -> 12925 | C3: 1000 | D3: =B3/C3 -> 12.925 | E3: TRUE | F3: 46035
A4: Blend de carne PREMIUM | B4: =(B34*0.35)+(B35*0.5)+(B36*0.15) -> 11115 | C4: 1000 | D4: =B4/C4 -> 11.115 | E4: TRUE | F4: 46058
A5: Medallon Veggie | B5: 700 | C5: 1 | D5: =C5*B5 -> 700 | E5: TRUE
A6: Bondiola de cerdo | B6: =(B29 * 2) + (B30 * 2) + (B31 * 0.5) -> 14485.82 | C6: 3000 | D6: =(B6/C6)*1 -> 4.8286067 | E6: TRUE
A7: Cheedar feteado Milkaut | B7: 129911 | C7: 576 | D7: =B7/C7 -> 225.53993 | E7: TRUE
A8: Pan chico de papa TBB | B8: 534 | C8: 1 | D8: =B8/C8 -> 534 | E8: TRUE
A9: Pan TBB | B9: 648 | C9: 1 | D9: =B9/C9 -> 648 | E9: TRUE
A10: Pan chiquito 40 gr | B10: 250 | C10: 1 | D10: =B10/C10 -> 250 | E10: TRUE | F10: 46045
A11: Papas bastón SIMPLOT Extra Crunch | B11: 52032.62 | C11: 15000 | D11: =B11/C11 -> 3.4688413 | E11: TRUE
A12: Aros de Cebolla | B12: 9181.21 | C12: 1000 | D12: =B12/C12 -> 9.18121 | E12: TRUE
A13: Nuggets de Pollo | B13: 40338.35 | C13: 3000 | D13: =B13/C13 -> 13.446117 | E13: TRUE
A14: Cheddar liquido | B14: 25480.5 | C14: 3500 | D14: =B14/C14 -> 7.2801429 | E14: TRUE | F14: 46045
A15: Bacon | B15: 5633.26 | C15: 1000 | D15: =B15/C15 -> 5.63326 | E15: TRUE
A16: Sal porción | B16: 8231.74 | C16: 1000 | D16: =B16/C16 -> 8.23174 | E16: TRUE
A17: Aceite | B17: 63000 | C17: 30 | D17: =B17/C17 -> 2100 | E17: TRUE
A18: Salsa TASTY | B18: 10000 | C18: 1000 | D18: =B18/C18 -> 10 | E18: TRUE
A19: Postre Oreo | B19: 2800 | C19: 1 | D19: =B19/C19 -> 2800 | E19: TRUE
A20: Postre Chocotorta | B20: 2800 | C20: 1 | D20: =B20/C20 -> 2800 | E20: TRUE
A21: Salsa Queso Azul | B21: 5000 | C21: 1000 | D21: =B21/C21 -> 5 | E21: FALSE
A22: Salsa WLB | B22: 10000 | C22: 1000 | D22: =B22/C22 -> 10 | E22: FALSE
A23: Huevo | B23: 6800 | C23: 30 | D23: =B23/C23 -> 226.66667 | E23: TRUE
A24: Pepino en vinagre | B24: 18000 | C24: 1500 | D24: =B24/C24 -> 12 | E24: TRUE
A25: Salsa de Dips | B25: 5375.14 | C25: 1000 | D25: =B25/C25 -> 5.37514 | E25: FALSE
A26: Ketchup pouch | B26: 10847 | C26: 3000 | D26: =B26/C26 -> 3.6156667 | E26: FALSE
... A33: Lechuga | B33: 5000 | C33: 1000 | D33: =B33/C33 -> 5 | E33: TRUE
A34: Tapa de asado (NOVILLO) | B34: 14900 | C34: 1000 | D34: =B34/C34 -> 14.9 | E34: TRUE | F34: 46058
A35: Roas Beef (NOVILLO) | B35: 11500 | C35: 1000 | D35: =B35/C35 -> 11.5 | E35: TRUE | F35: 46058
A36: Grasa de Pella | B36: 1000 | C36: 1000 | D36: =B36/C36 -> 1 | E36: TRUE | F36: 46058
A37: Tapa de asado | B37: 14300 | C37: 1000 | D37: =B37/C37 -> 14.3 | E37: TRUE | F37: 46035
A38: Falda deshuesada | B38: 11000 | C38: 1000 | D38: =B38/C38 -> 11 | E38: TRUE | F38: 46035
A39: Roast beef | B39: 13200 | C39: 1000 | D39: =B39/C39 -> 13.2 | E39: TRUE | F39: 46035
A40: Bebidas | E40: FALSE
A41: Pepsi Black | B41: 4548.6 | C41: 6 | D41: =B41/C41 -> 758.1 | E41: TRUE | F41: 46035
A42: Pepsi | B42: 4623.18 | C42: 6 | D42: =B42/C42 -> 770.53 | E42: TRUE | F42: 46035
A43: Mirinda | B43: 4548.68 | C43: 6 | D43: =B43/C43 -> 758.11333 | E43: TRUE | F43: 46035
A44: Bebida lata | B44: =(B43+B42+B41)/3 -> 4573.4867 | C44: 6 | D44: =B44/C44 -> 762.24778 | E44: TRUE | F44: 46035
A45: Cerveza tirada | B45: =(105300+215545+353295+110245+110245+245333.6)/6 -> 189993.93 | C45: 50 | D45: =B45/C45 -> 3799.8787 | E45: TRUE
A46: Pinta de cerveza | B46: =D45/2 -> 1899.9393 | C46: 1 | D46: =B46/C46 -> 1899.9393 | E46: TRUE
A47: Media Pinta de cerveza | B47: =D45/4 -> 949.96967 | C47: 1 | D47: =B47/C47 -> 949.96967 | E47: TRUE
...

Sheet CMV DIARIO
A1: PRODUCTOS | B1: TOTAL | C1: COSTO UNITARIO | D1: COSTO TOTAL | E1: CMV | F1: CMV
A2: DIA LABORAL | B2: 15 | C2: =PROPER(TEXT(DATE(2026, 2, B2), "dddd")) -> Domingo | E2: TURNO A | F2: TURNO B
A3: =IFERROR(__xludf.DUMMYFUNCTION("QUERY({IMPORTRANGE(""1gFO4fFAF8uaSQckGNdL2ULC0kQjiaTn7HExgq5kTGAk"",""VENTAS""&B2&""!B2:C101"");IMPORTRANGE(""1gFO4fFAF8uaSQckGNdL2ULC0kQjiaTn7HExgq5kTGAk"",""VENTAS""&B2&""!F2:G101"")},""Select Col1, sum(Col2) where Col1 is not null group by Col1 label s"&"um(Col2) 'Total'"",0)"),"") | B3: =IFERROR(__xludf.DUMMYFUNCTION("""COMPUTED_VALUE"""),"Total") -> Total
A4: =IFERROR(__xludf.DUMMYFUNCTION("""COMPUTED_VALUE"""),"AGUA MANZANA H20") -> AGUA MANZANA H20 | B4: =IFERROR(__xludf.DUMMYFUNCTION("""COMPUTED_VALUE"""),1) -> 1 | C4: =IFERROR(__xludf.DUMMYFUNCTION("INDEX(RECETAS!E:E, MAX(FILTER(ROW(RECETAS!A:A), RECETAS!A:A=A4)) + 1)"),717.358333333333) -> 717.35833 | D4: =C4*B4 -> 717.35833 | E4: =IFERROR(__xludf.DUMMYFUNCTION("IFNA(FILTER('Febrero 2026'!C3:D34, 'Febrero 2026'!B3:B34 = B2), ""Fecha no encontrada"")"),288800) -> 288800 | F4: =IFERROR(__xludf.DUMMYFUNCTION("""COMPUTED_VALUE"""),315500) -> 315500
A5: =IFERROR(__xludf.DUMMYFUNCTION("""COMPUTED_VALUE"""),"AGUA MINERAL") -> AGUA MINERAL | B5: =IFERROR(__xludf.DUMMYFUNCTION("""COMPUTED_VALUE"""),4) -> 4 | C5: =IFERROR(__xludf.DUMMYFUNCTION("INDEX(RECETAS!E:E, MAX(FILTER(ROW(RECETAS!A:A), RECETAS!A:A=A5)) + 1)"),920.664166666666) -> 920.66417 | D5: =C5*B5 -> 3682.6567
A6: =IFERROR(__xludf.DUMMYFUNCTION("""COMPUTED_VALUE"""),"AGUA POMELO H20") -> AGUA POMELO H20 | B6: =IFERROR(__xludf.DUMMYFUNCTION("""COMPUTED_VALUE"""),1) -> 1 | C6: =IFERROR(__xludf.DUMMYFUNCTION("INDEX(RECETAS!E:E, MAX(FILTER(ROW(RECETAS!A:A), RECETAS!A:A=A6)) + 1)"),717.375) -> 717.375 | D6: =C6*B6 -> 717.375
A7: =IFERROR(__xludf.DUMMYFUNCTION("""COMPUTED_VALUE"""),"AMERICAN BURGER") -> AMERICAN BURGER | B7: =IFERROR(__xludf.DUMMYFUNCTION("""COMPUTED_VALUE"""),3) -> 3 | C7: =IFERROR(__xludf.DUMMYFUNCTION("INDEX(RECETAS!E:E, MAX(FILTER(ROW(RECETAS!A:A), RECETAS!A:A=A7)) + 1)"),5886.03157939627) -> 5886.0316 | D7: =C7*B7 -> 17658.095
A8: =IFERROR(__xludf.DUMMYFUNCTION("""COMPUTED_VALUE"""),"BLUE CHEESE") -> BLUE CHEESE | B8: =IFERROR(__xludf.DUMMYFUNCTION("""COMPUTED_VALUE"""),1) -> 1 | C8: =IFERROR(__xludf.DUMMYFUNCTION("INDEX(RECETAS!E:E, MAX(FILTER(ROW(RECETAS!A:A), RECETAS!A:A=A8)) + 1)"),5298.53157939627) -> 5298.5316 | D8: =C8*B8 -> 5298.5316
A9: =IFERROR(__xludf.DUMMYFUNCTION("""COMPUTED_VALUE"""),"CHEESE BACON") -> CHEESE BACON | B9: =IFERROR(__xludf.DUMMYFUNCTION("""COMPUTED_VALUE"""),10) -> 10 | C9: =IFERROR(__xludf.DUMMYFUNCTION("INDEX(RECETAS!E:E, MAX(FILTER(ROW(RECETAS!A:A), RECETAS!A:A=A9)) + 1)"),5183.03047939627) -> 5183.0305 | D9: =C9*B9 -> 51830.305
A10: =IFERROR(__xludf.DUMMYFUNCTION("""COMPUTED_VALUE"""),"DOBLE CUARTO") -> DOBLE CUARTO | B10: =IFERROR(__xludf.DUMMYFUNCTION("""COMPUTED_VALUE"""),1) -> 1 | C10: =IFERROR(__xludf.DUMMYFUNCTION("INDEX(RECETAS!E:E, MAX(FILTER(ROW(RECETAS!A:A), RECETAS!A:A=A10)) + 1)"),5326.66684303263) -> 5326.6668 | D10: =C10*B10 -> 5326.6668
A11: =IFERROR(__xludf.DUMMYFUNCTION("""COMPUTED_VALUE"""),"EXTRA MEDALLON") -> EXTRA MEDALLON | B11: =IFERROR(__xludf.DUMMYFUNCTION("""COMPUTED_VALUE"""),3) -> 3 | C11: =IFERROR(__xludf.DUMMYFUNCTION("INDEX(RECETAS!E:E, MAX(FILTER(ROW(RECETAS!A:A), RECETAS!A:A=A11)) + 1)"),1421.75) -> 1421.75 | D11: =C11*B11 -> 4265.25
A12: =IFERROR(__xludf.DUMMYFUNCTION("""COMPUTED_VALUE"""),"HUMPTY BURGER") -> HUMPTY BURGER | B12: =IFERROR(__xludf.DUMMYFUNCTION("""COMPUTED_VALUE"""),6) -> 6 | C12: =IFERROR(__xludf.DUMMYFUNCTION("INDEX(RECETAS!E:E, MAX(FILTER(ROW(RECETAS!A:A), RECETAS!A:A=A12)) + 1)"),5409.69714606293) -> 5409.6971 | D12: =C12*B12 -> 32458.183
A13: =IFERROR(__xludf.DUMMYFUNCTION("""COMPUTED_VALUE"""),"JIMMY BURGER") -> JIMMY BURGER | B13: =IFERROR(__xludf.DUMMYFUNCTION("""COMPUTED_VALUE"""),1) -> 1 | C13: =IFERROR(__xludf.DUMMYFUNCTION("INDEX(RECETAS!E:E, MAX(FILTER(ROW(RECETAS!A:A), RECETAS!A:A=A13)) + 1)"),3923.49054884071) -> 3923.4905 | D13: =C13*B13 -> 3923.4905
A14: =IFERROR(__xludf.DUMMYFUNCTION("""COMPUTED_VALUE"""),"MIGI BURGER") -> MIGI BURGER | B14: =IFERROR(__xludf.DUMMYFUNCTION("""COMPUTED_VALUE"""),2) -> 2 | C14: =IFERROR(__xludf.DUMMYFUNCTION("INDEX(RECETAS!E:E, MAX(FILTER(ROW(RECETAS!A:A), RECETAS!A:A=A14)) + 1)"),4209.03157939627) -> 4209.0316 | D14: =C14*B14 -> 8418.0632
A15: =IFERROR(__xludf.DUMMYFUNCTION("""COMPUTED_VALUE"""),"MIRINDA") -> MIRINDA | B15: =IFERROR(__xludf.DUMMYFUNCTION("""COMPUTED_VALUE"""),1) -> 1 | C15: =IFERROR(__xludf.DUMMYFUNCTION("INDEX(RECETAS!E:E, MAX(FILTER(ROW(RECETAS!A:A), RECETAS!A:A=A15)) + 1)"),758.113333333333) -> 758.11333 | D15: =C15*B15 -> 758.11333
A16: =IFERROR(__xludf.DUMMYFUNCTION("""COMPUTED_VALUE"""),"MOBY DICK") -> MOBY DICK | B16: =IFERROR(__xludf.DUMMYFUNCTION("""COMPUTED_VALUE"""),1) -> 1 | C16: =IFERROR(__xludf.DUMMYFUNCTION("INDEX(RECETAS!E:E, MAX(FILTER(ROW(RECETAS!A:A), RECETAS!A:A=A16)) + 1)"),8562.10924050738) -> 8562.1092 | D16: =C16*B16 -> 8562.1092
A17: =IFERROR(__xludf.DUMMYFUNCTION("""COMPUTED_VALUE"""),"NUGGETS X 6") -> NUGGETS X 6 | B17: =IFERROR(__xludf.DUMMYFUNCTION("""COMPUTED_VALUE"""),1) -> 1 | C17: =IFERROR(__xludf.DUMMYFUNCTION("INDEX(RECETAS!E:E, MAX(FILTER(ROW(RECETAS!A:A), RECETAS!A:A=A17)) + 1)"),1680.52117948717) -> 1680.5212 | D17: =C17*B17 -> 1680.5212
A18: =IFERROR(__xludf.DUMMYFUNCTION("""COMPUTED_VALUE"""),"ONION RINGS BURGER") -> ONION RINGS BURGER | B18: =IFERROR(__xludf.DUMMYFUNCTION("""COMPUTED_VALUE"""),2) -> 2 | C18: =IFERROR(__xludf.DUMMYFUNCTION("INDEX(RECETAS!E:E, MAX(FILTER(ROW(RECETAS!A:A), RECETAS!A:A=A18)) + 1)"),5660.1693127296) -> 5660.1693 | D18: =C18*B18 -> 11320.339
A19: =IFERROR(__xludf.DUMMYFUNCTION("""COMPUTED_VALUE"""),"PEPSI ") -> PEPSI | B19: =IFERROR(__xludf.DUMMYFUNCTION("""COMPUTED_VALUE"""),3) -> 3 | C19: =IFERROR(__xludf.DUMMYFUNCTION("INDEX(RECETAS!E:E, MAX(FILTER(ROW(RECETAS!A:A), RECETAS!A:A=A19)) + 1)"),770.53) -> 770.53 | D19: =C19*B19 -> 2311.59
A20: =IFERROR(__xludf.DUMMYFUNCTION("""COMPUTED_VALUE"""),"PORCION DE PAPAS") -> PORCION DE PAPAS | B20: =IFERROR(__xludf.DUMMYFUNCTION("""COMPUTED_VALUE"""),1) -> 1 | C20: =IFERROR(__xludf.DUMMYFUNCTION("INDEX(RECETAS!E:E, MAX(FILTER(ROW(RECETAS!A:A), RECETAS!A:A=A20)) + 1)"),2292.92034615384) -> 2292.9203 | D20: =C20*B20 -> 2292.9203
A21: =IFERROR(__xludf.DUMMYFUNCTION("""COMPUTED_VALUE"""),"PULLED PORK") -> PULLED PORK | B21: =IFERROR(__xludf.DUMMYFUNCTION("""COMPUTED_VALUE"""),2) -> 2 | C21: =IFERROR(__xludf.DUMMYFUNCTION("INDEX(RECETAS!E:E, MAX(FILTER(ROW(RECETAS!A:A), RECETAS!A:A=A21)) + 1)"),2652.60312106293) -> 2652.6031 | D21: =C21*B21 -> 5305.2062
A22: =IFERROR(__xludf.DUMMYFUNCTION("""COMPUTED_VALUE"""),"SEVEN-UP") -> SEVEN-UP | B22: =IFERROR(__xludf.DUMMYFUNCTION("""COMPUTED_VALUE"""),5) -> 5 | C22: =IFERROR(__xludf.DUMMYFUNCTION("INDEX(RECETAS!E:E, MAX(FILTER(ROW(RECETAS!A:A), RECETAS!A:A=A22)) + 1)"),758.113333333333) -> 758.11333 | D22: =C22*B22 -> 3790.5667
A23: =IFERROR(__xludf.DUMMYFUNCTION("""COMPUTED_VALUE"""),"SWEET BACON BURGER") -> SWEET BACON BURGER | B23: =IFERROR(__xludf.DUMMYFUNCTION("""COMPUTED_VALUE"""),1) -> 1 | C23: =IFERROR(__xludf.DUMMYFUNCTION("INDEX(RECETAS!E:E, MAX(FILTER(ROW(RECETAS!A:A), RECETAS!A:A=A23)) + 1)"),5148.53157939627) -> 5148.5316 | D23: =C23*B23 -> 5148.5316
A24: =IFERROR(__xludf.DUMMYFUNCTION("""COMPUTED_VALUE"""),"SWEET ONION") -> SWEET ONION | B24: =IFERROR(__xludf.DUMMYFUNCTION("""COMPUTED_VALUE"""),5) -> 5 | C24: =IFERROR(__xludf.DUMMYFUNCTION("INDEX(RECETAS!E:E, MAX(FILTER(ROW(RECETAS!A:A), RECETAS!A:A=A24)) + 1)"),5183.03047939627) -> 5183.0305 | D24: =C24*B24 -> 25915.152
A25: =IFERROR(__xludf.DUMMYFUNCTION("""COMPUTED_VALUE"""),"TASTY WLB") -> TASTY WLB | B25: =IFERROR(__xludf.DUMMYFUNCTION("""COMPUTED_VALUE"""),1) -> 1 | C25: =IFERROR(__xludf.DUMMYFUNCTION("INDEX(RECETAS!E:E, MAX(FILTER(ROW(RECETAS!A:A), RECETAS!A:A=A25)) + 1)"),5411.03157939627) -> 5411.0316 | D25: =C25*B25 -> 5411.0316
A26: =IFERROR(__xludf.DUMMYFUNCTION("""COMPUTED_VALUE"""),"TRIPLE CHEESE BACON") -> TRIPLE CHEESE BACON | B26: =IFERROR(__xludf.DUMMYFUNCTION("""COMPUTED_VALUE"""),1) -> 1 | C26: =IFERROR(__xludf.DUMMYFUNCTION("INDEX(RECETAS!E:E, MAX(FILTER(ROW(RECETAS!A:A), RECETAS!A:A=A26)) + 1)"),6830.32040995182) -> 6830.3204 | D26: =C26*B26 -> 6830.3204
C27: =IFERROR(__xludf.DUMMYFUNCTION("INDEX(RECETAS!E:E, MAX(FILTER(ROW(RECETAS!A:A), RECETAS!A:A=A27)) + 1)"),"") | D27: =C27*B27 -> #VALUE!
C28: =IFERROR(__xludf.DUMMYFUNCTION("INDEX(RECETAS!E:E, MAX(FILTER(ROW(RECETAS!A:A), RECETAS!A:A=A28)) + 1)"),"") | D28: =C28*B28 -> #VALUE!
C29: =IFERROR(__xludf.DUMMYFUNCTION("INDEX(RECETAS!E:E, MAX(FILTER(ROW(RECETAS!A:A), RECETAS!A:A=A29)) + 1)"),"") | D29: =C29*B29 -> #VALUE!
C30: =IFERROR(__xludf.DUMMYFUNCTION("INDEX(RECETAS!E:E, MAX(FILTER(ROW(RECETAS!A:A), RECETAS!A:A=A30)) + 1)"),"") | D30: =C30*B30 -> #VALUE!
C31: =IFERROR(__xludf.DUMMYFUNCTION("INDEX(RECETAS!E:E, MAX(FILTER(ROW(RECETAS!A:A), RECETAS!A:A=A31)) + 1)"),"") | D31: =C31*B31 -> #VALUE!
C32: =IFERROR(__xludf.DUMMYFUNCTION("INDEX(RECETAS!E:E, MAX(FILTER(ROW(RECETAS!A:A), RECETAS!A:A=A32)) + 1)"),"") | D32: =C32*B32 -> #VALUE!
D34: =SUM(D4:D33) -> #VALUE! | E34: =E4+F4*1 -> 604300 | F34: =D34/E34 -> #VALUE!

Sheet CMV TOTAL 12-2025
A1: PRODUCTOS | B1: TOTAL | C1: COSTO UNITARIO | D1: COSTO TOTAL | E1: CMV | F1: CMV
A3: =IFERROR(__xludf.DUMMYFUNCTION("QUERY(ResumenVentas!A:B, ""Select A, sum(B) where A is not null group by A label sum(B) 'TOTAL'"", 1)"),"Producto") -> Producto | B3: =IFERROR(__xludf.DUMMYFUNCTION("""COMPUTED_VALUE"""),"TOTAL") -> TOTAL
A4: =IFERROR(__xludf.DUMMYFUNCTION("""COMPUTED_VALUE"""),"AGUA MANZANA H20") -> AGUA MANZANA H20 | B4: =IFERROR(__xludf.DUMMYFUNCTION("""COMPUTED_VALUE"""),9) -> 9 | C4: =IFERROR(__xludf.DUMMYFUNCTION("INDEX(RECETAS!E:E, MAX(FILTER(ROW(RECETAS!A:A), RECETAS!A:A=A4)) + 1)"),717.358333333333) -> 717.35833 | D4: =C4*B4 -> 6456.225 | E4: 7692710 | F4: 13670420
A5: =IFERROR(__xludf.DUMMYFUNCTION("""COMPUTED_VALUE"""),"AGUA MINERAL") -> AGUA MINERAL | B5: =IFERROR(__xludf.DUMMYFUNCTION("""COMPUTED_VALUE"""),45) -> 45 | C5: =IFERROR(__xludf.DUMMYFUNCTION("INDEX(RECETAS!E:E, MAX(FILTER(ROW(RECETAS!A:A), RECETAS!A:A=A5)) + 1)"),920.664166666666) -> 920.66417 | D5: =C5*B5 -> 41429.887
A6: =IFERROR(__xludf.DUMMYFUNCTION("""COMPUTED_VALUE"""),"AGUA POMELO H20") -> AGUA POMELO H20 | B6: =IFERROR(__xludf.DUMMYFUNCTION("""COMPUTED_VALUE"""),40) -> 40 | C6: =IFERROR(__xludf.DUMMYFUNCTION("INDEX(RECETAS!E:E, MAX(FILTER(ROW(RECETAS!A:A), RECETAS!A:A=A6)) + 1)"),717.375) -> 717.375 | D6: =C6*B6 -> 28695
A7: =IFERROR(__xludf.DUMMYFUNCTION("""COMPUTED_VALUE"""),"AMERICAN BURGER") -> AMERICAN BURGER | B7: =IFERROR(__xludf.DUMMYFUNCTION("""COMPUTED_VALUE"""),87) -> 87 | C7: =IFERROR(__xludf.DUMMYFUNCTION("INDEX(RECETAS!E:E, MAX(FILTER(ROW(RECETAS!A:A), RECETAS!A:A=A7)) + 1)"),5886.03157939627) -> 5886.0316 | D7: =C7*B7 -> 512084.75
A8: =IFERROR(__xludf.DUMMYFUNCTION("""COMPUTED_VALUE"""),"AROS DE CEBOLLA") -> AROS DE CEBOLLA | B8: =IFERROR(__xludf.DUMMYFUNCTION("""COMPUTED_VALUE"""),7) -> 7 | C8: =IFERROR(__xludf.DUMMYFUNCTION("INDEX(RECETAS!E:E, MAX(FILTER(ROW(RECETAS!A:A), RECETAS!A:A=A8)) + 1)"),2027.49327948717) -> 2027.4933 | D8: =C8*B8 -> 14192.453
A9: =IFERROR(__xludf.DUMMYFUNCTION("""COMPUTED_VALUE"""),"BLUE CHEESE") -> BLUE CHEESE | B9: =IFERROR(__xludf.DUMMYFUNCTION("""COMPUTED_VALUE"""),35) -> 35 | C9: =IFERROR(__xludf.DUMMYFUNCTION("INDEX(RECETAS!E:E, MAX(FILTER(ROW(RECETAS!A:A), RECETAS!A:A=A9)) + 1)"),5298.53157939627) -> 5298.5316 | D9: =C9*B9 -> 185448.61
A10: =IFERROR(__xludf.DUMMYFUNCTION("""COMPUTED_VALUE"""),"BOTELLA DE CERVEZA") -> BOTELLA DE CERVEZA | B10: =IFERROR(__xludf.DUMMYFUNCTION("""COMPUTED_VALUE"""),11) -> 11 | C10: =IFERROR(__xludf.DUMMYFUNCTION("INDEX(RECETAS!E:E, MAX(FILTER(ROW(RECETAS!A:A), RECETAS!A:A=A10)) + 1)"),1899.93933333333) -> 1899.9393 | D10: =C10*B10 -> 20899.333
A11: =IFERROR(__xludf.DUMMYFUNCTION("""COMPUTED_VALUE"""),"CHEESE BACON") -> CHEESE BACON | B11: =IFERROR(__xludf.DUMMYFUNCTION("""COMPUTED_VALUE"""),172) -> 172 | C11: =IFERROR(__xludf.DUMMYFUNCTION("INDEX(RECETAS!E:E, MAX(FILTER(ROW(RECETAS!A:A), RECETAS!A:A=A11)) + 1)"),5183.03047939627) -> 5183.0305 | D11: =C11*B11 -> 891481.24
A12: =IFERROR(__xludf.DUMMYFUNCTION("""COMPUTED_VALUE"""),"CHEESE BURGER") -> CHEESE BURGER | B12: =IFERROR(__xludf.DUMMYFUNCTION("""COMPUTED_VALUE"""),3) -> 3 | C12: =IFERROR(__xludf.DUMMYFUNCTION("INDEX(RECETAS!E:E, MAX(FILTER(ROW(RECETAS!A:A), RECETAS!A:A=A12)) + 1)"),5073.90657939627) -> 5073.9066 | D12: =C12*B12 -> 15221.72
A13: =IFERROR(__xludf.DUMMYFUNCTION("""COMPUTED_VALUE"""),"CHEESE BURGER CANJE") -> CHEESE BURGER CANJE | B13: =IFERROR(__xludf.DUMMYFUNCTION("""COMPUTED_VALUE"""),8) -> 8 | C13: =IFERROR(__xludf.DUMMYFUNCTION("INDEX(RECETAS!E:E, MAX(FILTER(ROW(RECETAS!A:A), RECETAS!A:A=A13)) + 1)"),2086.06704059829) -> 2086.067 | D13: =C13*B13 -> 16688.536
A14: =IFERROR(__xludf.DUMMYFUNCTION("""COMPUTED_VALUE"""),"CRISPY BURGER") -> CRISPY BURGER | B14: =IFERROR(__xludf.DUMMYFUNCTION("""COMPUTED_VALUE"""),51) -> 51 | C14: =IFERROR(__xludf.DUMMYFUNCTION("INDEX(RECETAS!E:E, MAX(FILTER(ROW(RECETAS!A:A), RECETAS!A:A=A14)) + 1)"),5233.03047939627) -> 5233.0305 | D14: =C14*B14 -> 266884.55
A15: =IFERROR(__xludf.DUMMYFUNCTION("""COMPUTED_VALUE"""),"DOBLE CUARTO") -> DOBLE CUARTO | B15: =IFERROR(__xludf.DUMMYFUNCTION("""COMPUTED_VALUE"""),50) -> 50 | C15: =IFERROR(__xludf.DUMMYFUNCTION("INDEX(RECETAS!E:E, MAX(FILTER(ROW(RECETAS!A:A), RECETAS!A:A=A15)) + 1)"),5326.66684303263) -> 5326.6668 | D15: =C15*B15 -> 266333.34
A16: =IFERROR(__xludf.DUMMYFUNCTION("""COMPUTED_VALUE"""),"EXTRA MEDALLON") -> EXTRA MEDALLON | B16: =IFERROR(__xludf.DUMMYFUNCTION("""COMPUTED_VALUE"""),3) -> 3 | C16: =IFERROR(__xludf.DUMMYFUNCTION("INDEX(RECETAS!E:E, MAX(FILTER(ROW(RECETAS!A:A), RECETAS!A:A=A16)) + 1)"),1421.75) -> 1421.75 | D16: =C16*B16 -> 4265.25
A17: =IFERROR(__xludf.DUMMYFUNCTION("""COMPUTED_VALUE"""),"HUMPTY BURGER") -> HUMPTY BURGER | B17: =IFERROR(__xludf.DUMMYFUNCTION("""COMPUTED_VALUE"""),74) -> 74 | C17: =IFERROR(__xludf.DUMMYFUNCTION("INDEX(RECETAS!E:E, MAX(FILTER(ROW(RECETAS!A:A), RECETAS!A:A=A17)) + 1)"),5409.69714606293) -> 5409.6971 | D17: =C17*B17 -> 400317.59
A18: =IFERROR(__xludf.DUMMYFUNCTION("""COMPUTED_VALUE"""),"JIMMY BURGER") -> JIMMY BURGER | B18: =IFERROR(__xludf.DUMMYFUNCTION("""COMPUTED_VALUE"""),34) -> 34 | C18: =IFERROR(__xludf.DUMMYFUNCTION("INDEX(RECETAS!E:E, MAX(FILTER(ROW(RECETAS!A:A), RECETAS!A:A=A18)) + 1)"),3923.49054884071) -> 3923.4905 | D18: =C18*B18 -> 133398.68
A19: =IFERROR(__xludf.DUMMYFUNCTION("""COMPUTED_VALUE"""),"MEDALLON VEGGIE") -> MEDALLON VEGGIE | B19: =IFERROR(__xludf.DUMMYFUNCTION("""COMPUTED_VALUE"""),1) -> 1 | C19: =IFERROR(__xludf.DUMMYFUNCTION("INDEX(RECETAS!E:E, MAX(FILTER(ROW(RECETAS!A:A), RECETAS!A:A=A19)) + 1)"),700) -> 700 | D19: =C19*B19 -> 700
A20: =IFERROR(__xludf.DUMMYFUNCTION("""COMPUTED_VALUE"""),"MEDIA PINTA DE CERVEZA") -> MEDIA PINTA DE CERVEZA | B20: =IFERROR(__xludf.DUMMYFUNCTION("""COMPUTED_VALUE"""),64) -> 64 | C20: =IFERROR(__xludf.DUMMYFUNCTION("INDEX(RECETAS!E:E, MAX(FILTER(ROW(RECETAS!A:A), RECETAS!A:A=A20)) + 1)"),949.969666666666) -> 949.96967 | D20: =C20*B20 -> 60798.059
A21: =IFERROR(__xludf.DUMMYFUNCTION("""COMPUTED_VALUE"""),"MIGI BURGER") -> MIGI BURGER | B21: =IFERROR(__xludf.DUMMYFUNCTION("""COMPUTED_VALUE"""),164) -> 164 | C21: =IFERROR(__xludf.DUMMYFUNCTION("INDEX(RECETAS!E:E, MAX(FILTER(ROW(RECETAS!A:A), RECETAS!A:A=A21)) + 1)"),4209.03157939627) -> 4209.0316 | D21: =C21*B21 -> 690281.18
A22: =IFERROR(__xludf.DUMMYFUNCTION("""COMPUTED_VALUE"""),"MIRINDA") -> MIRINDA | B22: =IFERROR(__xludf.DUMMYFUNCTION("""COMPUTED_VALUE"""),36) -> 36 | C22: =IFERROR(__xludf.DUMMYFUNCTION("INDEX(RECETAS!E:E, MAX(FILTER(ROW(RECETAS!A:A), RECETAS!A:A=A22)) + 1)"),758.113333333333) -> 758.11333 | D22: =C22*B22 -> 27292.08
A23: =IFERROR(__xludf.DUMMYFUNCTION("""COMPUTED_VALUE"""),"MOBY DICK") -> MOBY DICK | B23: =IFERROR(__xludf.DUMMYFUNCTION("""COMPUTED_VALUE"""),70) -> 70 | C23: =IFERROR(__xludf.DUMMYFUNCTION("INDEX(RECETAS!E:E, MAX(FILTER(ROW(RECETAS!A:A), RECETAS!A:A=A23)) + 1)"),8562.10924050738) -> 8562.1092 | D23: =C23*B23 -> 599347.65
A24: =IFERROR(__xludf.DUMMYFUNCTION("""COMPUTED_VALUE"""),"NUGGETS X 10") -> NUGGETS X 10 | B24: =IFERROR(__xludf.DUMMYFUNCTION("""COMPUTED_VALUE"""),12) -> 12 | C24: =IFERROR(__xludf.DUMMYFUNCTION("INDEX(RECETAS!E:E, MAX(FILTER(ROW(RECETAS!A:A), RECETAS!A:A=A24)) + 1)"),2756.21051282051) -> 2756.2105 | D24: =C24*B24 -> 33074.526
A25: =IFERROR(__xludf.DUMMYFUNCTION("""COMPUTED_VALUE"""),"NUGGETS X 6") -> NUGGETS X 6 | B25: =IFERROR(__xludf.DUMMYFUNCTION("""COMPUTED_VALUE"""),5) -> 5 | C25: =IFERROR(__xludf.DUMMYFUNCTION("INDEX(RECETAS!E:E, MAX(FILTER(ROW(RECETAS!A:A), RECETAS!A:A=A25)) + 1)"),1680.52117948717) -> 1680.5212 | D25: =C25*B25 -> 8402.6059
A26: =IFERROR(__xludf.DUMMYFUNCTION("""COMPUTED_VALUE"""),"ONION RINGS BURGER") -> ONION RINGS BURGER | B26: =IFERROR(__xludf.DUMMYFUNCTION("""COMPUTED_VALUE"""),26) -> 26 | C26: =IFERROR(__xludf.DUMMYFUNCTION("INDEX(RECETAS!E:E, MAX(FILTER(ROW(RECETAS!A:A), RECETAS!A:A=A26)) + 1)"),5660.1693127296) -> 5660.1693 | D26: =C26*B26 -> 147164.4
A27: =IFERROR(__xludf.DUMMYFUNCTION("""COMPUTED_VALUE"""),"PEPSI ") -> PEPSI | B27: =IFERROR(__xludf.DUMMYFUNCTION("""COMPUTED_VALUE"""),204) -> 204 | C27: =IFERROR(__xludf.DUMMYFUNCTION("INDEX(RECETAS!E:E, MAX(FILTER(ROW(RECETAS!A:A), RECETAS!A:A=A27)) + 1)"),770.53) -> 770.53 | D27: =C27*B27 -> 157188.12
A28: =IFERROR(__xludf.DUMMYFUNCTION("""COMPUTED_VALUE"""),"PEPSI BLACK") -> PEPSI BLACK | B28: =IFERROR(__xludf.DUMMYFUNCTION("""COMPUTED_VALUE"""),43) -> 43 | C28: =IFERROR(__xludf.DUMMYFUNCTION("INDEX(RECETAS!E:E, MAX(FILTER(ROW(RECETAS!A:A), RECETAS!A:A=A28)) + 1)"),758.1) -> 758.1 | D28: =C28*B28 -> 32598.3
A29: =IFERROR(__xludf.DUMMYFUNCTION("""COMPUTED_VALUE"""),"PINTA DE CERVEZA") -> PINTA DE CERVEZA | B29: =IFERROR(__xludf.DUMMYFUNCTION("""COMPUTED_VALUE"""),2) -> 2 | C29: =IFERROR(__xludf.DUMMYFUNCTION("INDEX(RECETAS!E:E, MAX(FILTER(ROW(RECETAS!A:A), RECETAS!A:A=A29)) + 1)"),1899.93933333333) -> 1899.9393 | D29: =C29*B29 -> 3799.8787
A30: =IFERROR(__xludf.DUMMYFUNCTION("""COMPUTED_VALUE"""),"PORCION DE PAPAS") -> PORCION DE PAPAS | B30: =IFERROR(__xludf.DUMMYFUNCTION("""COMPUTED_VALUE"""),19) -> 19 | C30: =IFERROR(__xludf.DUMMYFUNCTION("INDEX(RECETAS!E:E, MAX(FILTER(ROW(RECETAS!A:A), RECETAS!A:A=A30)) + 1)"),2292.92034615384) -> 2292.9203 | D30: =C30*B30 -> 43565.487
A31: =IFERROR(__xludf.DUMMYFUNCTION("""COMPUTED_VALUE"""),"PORCION DE PAPAS CON CHEDDAR Y BACON") -> PORCION DE PAPAS CON CHEDDAR Y BACON | B31: =IFERROR(__xludf.DUMMYFUNCTION("""COMPUTED_VALUE"""),6) -> 6 | C31: =IFERROR(__xludf.DUMMYFUNCTION("INDEX(RECETAS!E:E, MAX(FILTER(ROW(RECETAS!A:A), RECETAS!A:A=A31)) + 1)"),3229.7962032967) -> 3229.7962 | D31: =C31*B31 -> 19378.777
A32: =IFERROR(__xludf.DUMMYFUNCTION("""COMPUTED_VALUE"""),"PORCION DE PAPAS Y CHEDDAR") -> PORCION DE PAPAS Y CHEDDAR | B32: =IFERROR(__xludf.DUMMYFUNCTION("""COMPUTED_VALUE"""),7) -> 7 | C32: =IFERROR(__xludf.DUMMYFUNCTION("INDEX(RECETAS!E:E, MAX(FILTER(ROW(RECETAS!A:A), RECETAS!A:A=A32)) + 1)"),2948.1332032967) -> 2948.1332 | D32: =C32*B32 -> 20636.932
A33: =IFERROR(__xludf.DUMMYFUNCTION("""COMPUTED_VALUE"""),"POSTRE CHOCOTORTA") -> POSTRE CHOCOTORTA | B33: =IFERROR(__xludf.DUMMYFUNCTION("""COMPUTED_VALUE"""),13) -> 13 | C33: =IFERROR(__xludf.DUMMYFUNCTION("INDEX(RECETAS!E:E, MAX(FILTER(ROW(RECETAS!A:A), RECETAS!A:A=A33)) + 1)"),2800) -> 2800 | D33: =C33*B33 -> 36400
A34: =IFERROR(__xludf.DUMMYFUNCTION("""COMPUTED_VALUE"""),"POSTRE OREO") -> POSTRE OREO | B34: =IFERROR(__xludf.DUMMYFUNCTION("""COMPUTED_VALUE"""),12) -> 12 | C34: =IFERROR(__xludf.DUMMYFUNCTION("INDEX(RECETAS!E:E, MAX(FILTER(ROW(RECETAS!A:A), RECETAS!A:A=A34)) + 1)"),2800) -> 2800 | D34: =C34*B34 -> 33600
A35: =IFERROR(__xludf.DUMMYFUNCTION("""COMPUTED_VALUE"""),"PULLED PORK") -> PULLED PORK | B35: =IFERROR(__xludf.DUMMYFUNCTION("""COMPUTED_VALUE"""),63) -> 63 | C35: =IFERROR(__xludf.DUMMYFUNCTION("INDEX(RECETAS!E:E, MAX(FILTER(ROW(RECETAS!A:A), RECETAS!A:A=A35)) + 1)"),2652.60312106293) -> 2652.6031 | D35: =C35*B35 -> 167114
A36: =IFERROR(__xludf.DUMMYFUNCTION("""COMPUTED_VALUE"""),"SEVEN-UP") -> SEVEN-UP | B36: =IFERROR(__xludf.DUMMYFUNCTION("""COMPUTED_VALUE"""),126) -> 126 | C36: =IFERROR(__xludf.DUMMYFUNCTION("INDEX(RECETAS!E:E, MAX(FILTER(ROW(RECETAS!A:A), RECETAS!A:A=A36)) + 1)"),758.113333333333) -> 758.11333 | D36: =C36*B36 -> 95522.28
A37: =IFERROR(__xludf.DUMMYFUNCTION("""COMPUTED_VALUE"""),"SWEET BACON BURGER") -> SWEET BACON BURGER | B37: =IFERROR(__xludf.DUMMYFUNCTION("""COMPUTED_VALUE"""),31) -> 31 | C37: =IFERROR(__xludf.DUMMYFUNCTION("INDEX(RECETAS!E:E, MAX(FILTER(ROW(RECETAS!A:A), RECETAS!A:A=A37)) + 1)"),5148.53157939627) -> 5148.5316 | D37: =C37*B37 -> 159604.48
A38: =IFERROR(__xludf.DUMMYFUNCTION("""COMPUTED_VALUE"""),"SWEET ONION") -> SWEET ONION | B38: =IFERROR(__xludf.DUMMYFUNCTION("""COMPUTED_VALUE"""),68) -> 68 | C38: =IFERROR(__xludf.DUMMYFUNCTION("INDEX(RECETAS!E:E, MAX(FILTER(ROW(RECETAS!A:A), RECETAS!A:A=A38)) + 1)"),5183.03047939627) -> 5183.0305 | D38: =C38*B38 -> 352446.07
A39: =IFERROR(__xludf.DUMMYFUNCTION("""COMPUTED_VALUE"""),"TASTY WLB") -> TASTY WLB | B39: =IFERROR(__xludf.DUMMYFUNCTION("""COMPUTED_VALUE"""),41) -> 41 | C39: =IFERROR(__xludf.DUMMYFUNCTION("INDEX(RECETAS!E:E, MAX(FILTER(ROW(RECETAS!A:A), RECETAS!A:A=A39)) + 1)"),5411.03157939627) -> 5411.0316 | D39: =C39*B39 -> 221852.29
A40: =IFERROR(__xludf.DUMMYFUNCTION("""COMPUTED_VALUE"""),"TRIPLE CHEESE BACON") -> TRIPLE CHEESE BACON | B40: =IFERROR(__xludf.DUMMYFUNCTION("""COMPUTED_VALUE"""),64) -> 64 | C40: =IFERROR(__xludf.DUMMYFUNCTION("INDEX(RECETAS!E:E, MAX(FILTER(ROW(RECETAS!A:A), RECETAS!A:A=A40)) + 1)"),6830.32040995182) -> 6830.3204 | D40: =C40*B40 -> 437140.51
A41: =IFERROR(__xludf.DUMMYFUNCTION("""COMPUTED_VALUE"""),"VEGGIE BURGER") -> VEGGIE BURGER | B41: =IFERROR(__xludf.DUMMYFUNCTION("""COMPUTED_VALUE"""),26) -> 26 | C41: =IFERROR(__xludf.DUMMYFUNCTION("INDEX(RECETAS!E:E, MAX(FILTER(ROW(RECETAS!A:A), RECETAS!A:A=A41)) + 1)"),2674.4117877296) -> 2674.4118 | D41: =C41*B41 -> 69534.706
...

Sheet CMV TOTAL 01-2026
A1: PRODUCTOS | B1: TOTAL | C1: COSTO UNITARIO | D1: COSTO TOTAL | E1: CMV | F1: CMV
A3: =IFERROR(__xludf.DUMMYFUNCTION("QUERY(ResumenVentas!A:B, ""Select A, sum(B) where A is not null group by A label sum(B) 'TOTAL'"", 1)"),"Producto") -> Producto | B3: =IFERROR(__xludf.DUMMYFUNCTION("""COMPUTED_VALUE"""),"TOTAL") -> TOTAL
A4: =IFERROR(__xludf.DUMMYFUNCTION("""COMPUTED_VALUE"""),"AGUA MANZANA H20") -> AGUA MANZANA H20 | B4: =IFERROR(__xludf.DUMMYFUNCTION("""COMPUTED_VALUE"""),9) -> 9 | C4: =IFERROR(__xludf.DUMMYFUNCTION("INDEX(RECETAS!E:E, MAX(FILTER(ROW(RECETAS!A:A), RECETAS!A:A=A4)) + 1)"),717.358333333333) -> 717.35833 | D4: =C4*B4 -> 6456.225 | E4: =#REF! -> #REF! | F4: =#REF! -> #REF!
A5: =IFERROR(__xludf.DUMMYFUNCTION("""COMPUTED_VALUE"""),"AGUA MINERAL") -> AGUA MINERAL | B5: =IFERROR(__xludf.DUMMYFUNCTION("""COMPUTED_VALUE"""),45) -> 45 | C5: =IFERROR(__xludf.DUMMYFUNCTION("INDEX(RECETAS!E:E, MAX(FILTER(ROW(RECETAS!A:A), RECETAS!A:A=A5)) + 1)"),920.664166666666) -> 920.66417 | D5: =C5*B5 -> 41429.887
A6: =IFERROR(__xludf.DUMMYFUNCTION("""COMPUTED_VALUE"""),"AGUA POMELO H20") -> AGUA POMELO H20 | B6: =IFERROR(__xludf.DUMMYFUNCTION("""COMPUTED_VALUE"""),40) -> 40 | C6: =IFERROR(__xludf.DUMMYFUNCTION("INDEX(RECETAS!E:E, MAX(FILTER(ROW(RECETAS!A:A), RECETAS!A:A=A6)) + 1)"),717.375) -> 717.375 | D6: =C6*B6 -> 28695
A7: =IFERROR(__xludf.DUMMYFUNCTION("""COMPUTED_VALUE"""),"AMERICAN BURGER") -> AMERICAN BURGER | B7: =IFERROR(__xludf.DUMMYFUNCTION("""COMPUTED_VALUE"""),87) -> 87 | C7: =IFERROR(__xludf.DUMMYFUNCTION("INDEX(RECETAS!E:E, MAX(FILTER(ROW(RECETAS!A:A), RECETAS!A:A=A7)) + 1)"),5886.03157939627) -> 5886.0316 | D7: =C7*B7 -> 512084.75
A8: =IFERROR(__xludf.DUMMYFUNCTION("""COMPUTED_VALUE"""),"AROS DE CEBOLLA") -> AROS DE CEBOLLA | B8: =IFERROR(__xludf.DUMMYFUNCTION("""COMPUTED_VALUE"""),7) -> 7 | C8: =IFERROR(__xludf.DUMMYFUNCTION("INDEX(RECETAS!E:E, MAX(FILTER(ROW(RECETAS!A:A), RECETAS!A:A=A8)) + 1)"),2027.49327948717) -> 2027.4933 | D8: =C8*B8 -> 14192.453
A9: =IFERROR(__xludf.DUMMYFUNCTION("""COMPUTED_VALUE"""),"BLUE CHEESE") -> BLUE CHEESE | B9: =IFERROR(__xludf.DUMMYFUNCTION("""COMPUTED_VALUE"""),35) -> 35 | C9: =IFERROR(__xludf.DUMMYFUNCTION("INDEX(RECETAS!E:E, MAX(FILTER(ROW(RECETAS!A:A), RECETAS!A:A=A9)) + 1)"),5298.53157939627) -> 5298.5316 | D9: =C9*B9 -> 185448.61
A10: =IFERROR(__xludf.DUMMYFUNCTION("""COMPUTED_VALUE"""),"BOTELLA DE CERVEZA") -> BOTELLA DE CERVEZA | B10: =IFERROR(__xludf.DUMMYFUNCTION("""COMPUTED_VALUE"""),11) -> 11 | C10: =IFERROR(__xludf.DUMMYFUNCTION("INDEX(RECETAS!E:E, MAX(FILTER(ROW(RECETAS!A:A), RECETAS!A:A=A10)) + 1)"),1899.93933333333) -> 1899.9393 | D10: =C10*B10 -> 20899.333
A11: =IFERROR(__xludf.DUMMYFUNCTION("""COMPUTED_VALUE"""),"CHEESE BACON") -> CHEESE BACON | B11: =IFERROR(__xludf.DUMMYFUNCTION("""COMPUTED_VALUE"""),172) -> 172 | C11: =IFERROR(__xludf.DUMMYFUNCTION("INDEX(RECETAS!E:E, MAX(FILTER(ROW(RECETAS!A:A), RECETAS!A:A=A11)) + 1)"),5183.03047939627) -> 5183.0305 | D11: =C11*B11 -> 891481.24
A12: =IFERROR(__xludf.DUMMYFUNCTION("""COMPUTED_VALUE"""),"CHEESE BURGER") -> CHEESE BURGER | B12: =IFERROR(__xludf.DUMMYFUNCTION("""COMPUTED_VALUE"""),3) -> 3 | C12: =IFERROR(__xludf.DUMMYFUNCTION("INDEX(RECETAS!E:E, MAX(FILTER(ROW(RECETAS!A:A), RECETAS!A:A=A12)) + 1)"),5073.90657939627) -> 5073.9066 | D12: =C12*B12 -> 15221.72
A13: =IFERROR(__xludf.DUMMYFUNCTION("""COMPUTED_VALUE"""),"CHEESE BURGER CANJE") -> CHEESE BURGER CANJE | B13: =IFERROR(__xludf.DUMMYFUNCTION("""COMPUTED_VALUE"""),8) -> 8 | C13: =IFERROR(__xludf.DUMMYFUNCTION("INDEX(RECETAS!E:E, MAX(FILTER(ROW(RECETAS!A:A), RECETAS!A:A=A13)) + 1)"),2086.06704059829) -> 2086.067 | D13: =C13*B13 -> 16688.536
A14: =IFERROR(__xludf.DUMMYFUNCTION("""COMPUTED_VALUE"""),"CRISPY BURGER") -> CRISPY BURGER | B14: =IFERROR(__xludf.DUMMYFUNCTION("""COMPUTED_VALUE"""),51) -> 51 | C14: =IFERROR(__xludf.DUMMYFUNCTION("INDEX(RECETAS!E:E, MAX(FILTER(ROW(RECETAS!A:A), RECETAS!A:A=A14)) + 1)"),5233.03047939627) -> 5233.0305 | D14: =C14*B14 -> 266884.55
A15: =IFERROR(__xludf.DUMMYFUNCTION("""COMPUTED_VALUE"""),"DOBLE CUARTO") -> DOBLE CUARTO | B15: =IFERROR(__xludf.DUMMYFUNCTION("""COMPUTED_VALUE"""),50) -> 50 | C15: =IFERROR(__xludf.DUMMYFUNCTION("INDEX(RECETAS!E:E, MAX(FILTER(ROW(RECETAS!A:A), RECETAS!A:A=A15)) + 1)"),5326.66684303263) -> 5326.6668 | D15: =C15*B15 -> 266333.34
A16: =IFERROR(__xludf.DUMMYFUNCTION("""COMPUTED_VALUE"""),"EXTRA MEDALLON") -> EXTRA MEDALLON | B16: =IFERROR(__xludf.DUMMYFUNCTION("""COMPUTED_VALUE"""),3) -> 3 | C16: =IFERROR(__xludf.DUMMYFUNCTION("INDEX(RECETAS!E:E, MAX(FILTER(ROW(RECETAS!A:A), RECETAS!A:A=A16)) + 1)"),1421.75) -> 1421.75 | D16: =C16*B16 -> 4265.25
A17: =IFERROR(__xludf.DUMMYFUNCTION("""COMPUTED_VALUE"""),"HUMPTY BURGER") -> HUMPTY BURGER | B17: =IFERROR(__xludf.DUMMYFUNCTION("""COMPUTED_VALUE"""),74) -> 74 | C17: =IFERROR(__xludf.DUMMYFUNCTION("INDEX(RECETAS!E:E, MAX(FILTER(ROW(RECETAS!A:A), RECETAS!A:A=A17)) + 1)"),5409.69714606293) -> 5409.6971 | D17: =C17*B17 -> 400317.59
A18: =IFERROR(__xludf.DUMMYFUNCTION("""COMPUTED_VALUE"""),"JIMMY BURGER") -> JIMMY BURGER | B18: =IFERROR(__xludf.DUMMYFUNCTION("""COMPUTED_VALUE"""),34) -> 34 | C18: =IFERROR(__xludf.DUMMYFUNCTION("INDEX(RECETAS!E:E, MAX(FILTER(ROW(RECETAS!A:A), RECETAS!A:A=A18)) + 1)"),3923.49054884071) -> 3923.4905 | D18: =C18*B18 -> 133398.68
A19: =IFERROR(__xludf.DUMMYFUNCTION("""COMPUTED_VALUE"""),"MEDALLON VEGGIE") -> MEDALLON VEGGIE | B19: =IFERROR(__xludf.DUMMYFUNCTION("""COMPUTED_VALUE"""),1) -> 1 | C19: =IFERROR(__xludf.DUMMYFUNCTION("INDEX(RECETAS!E:E, MAX(FILTER(ROW(RECETAS!A:A), RECETAS!A:A=A19)) + 1)"),700) -> 700 | D19: =C19*B19 -> 700
A20: =IFERROR(__xludf.DUMMYFUNCTION("""COMPUTED_VALUE"""),"MEDIA PINTA DE CERVEZA") -> MEDIA PINTA DE CERVEZA | B20: =IFERROR(__xludf.DUMMYFUNCTION("""COMPUTED_VALUE"""),64) -> 64 | C20: =IFERROR(__xludf.DUMMYFUNCTION("INDEX(RECETAS!E:E, MAX(FILTER(ROW(RECETAS!A:A), RECETAS!A:A=A20)) + 1)"),949.969666666666) -> 949.96967 | D20: =C20*B20 -> 60798.059
A21: =IFERROR(__xludf.DUMMYFUNCTION("""COMPUTED_VALUE"""),"MIGI BURGER") -> MIGI BURGER | B21: =IFERROR(__xludf.DUMMYFUNCTION("""COMPUTED_VALUE"""),164) -> 164 | C21: =IFERROR(__xludf.DUMMYFUNCTION("INDEX(RECETAS!E:E, MAX(FILTER(ROW(RECETAS!A:A), RECETAS!A:A=A21)) + 1)"),4209.03157939627) -> 4209.0316 | D21: =C21*B21 -> 690281.18
A22: =IFERROR(__xludf.DUMMYFUNCTION("""COMPUTED_VALUE"""),"MIRINDA") -> MIRINDA | B22: =IFERROR(__xludf.DUMMYFUNCTION("""COMPUTED_VALUE"""),36) -> 36 | C22: =IFERROR(__xludf.DUMMYFUNCTION("INDEX(RECETAS!E:E, MAX(FILTER(ROW(RECETAS!A:A), RECETAS!A:A=A22)) + 1)"),758.113333333333) -> 758.11333 | D22: =C22*B22 -> 27292.08
A23: =IFERROR(__xludf.DUMMYFUNCTION("""COMPUTED_VALUE"""),"MOBY DICK") -> MOBY DICK | B23: =IFERROR(__xludf.DUMMYFUNCTION("""COMPUTED_VALUE"""),70) -> 70 | C23: =IFERROR(__xludf.DUMMYFUNCTION("INDEX(RECETAS!E:E, MAX(FILTER(ROW(RECETAS!A:A), RECETAS!A:A=A23)) + 1)"),8562.10924050738) -> 8562.1092 | D23: =C23*B23 -> 599347.65
A24: =IFERROR(__xludf.DUMMYFUNCTION("""COMPUTED_VALUE"""),"NUGGETS X 10") -> NUGGETS X 10 | B24: =IFERROR(__xludf.DUMMYFUNCTION("""COMPUTED_VALUE"""),12) -> 12 | C24: =IFERROR(__xludf.DUMMYFUNCTION("INDEX(RECETAS!E:E, MAX(FILTER(ROW(RECETAS!A:A), RECETAS!A:A=A24)) + 1)"),2756.21051282051) -> 2756.2105 | D24: =C24*B24 -> 33074.526
A25: =IFERROR(__xludf.DUMMYFUNCTION("""COMPUTED_VALUE"""),"NUGGETS X 6") -> NUGGETS X 6 | B25: =IFERROR(__xludf.DUMMYFUNCTION("""COMPUTED_VALUE"""),5) -> 5 | C25: =IFERROR(__xludf.DUMMYFUNCTION("INDEX(RECETAS!E:E, MAX(FILTER(ROW(RECETAS!A:A), RECETAS!A:A=A25)) + 1)"),1680.52117948717) -> 1680.5212 | D25: =C25*B25 -> 8402.6059
A26: =IFERROR(__xludf.DUMMYFUNCTION("""COMPUTED_VALUE"""),"ONION RINGS BURGER") -> ONION RINGS BURGER | B26: =IFERROR(__xludf.DUMMYFUNCTION("""COMPUTED_VALUE"""),26) -> 26 | C26: =IFERROR(__xludf.DUMMYFUNCTION("INDEX(RECETAS!E:E, MAX(FILTER(ROW(RECETAS!A:A), RECETAS!A:A=A26)) + 1)"),5660.1693127296) -> 5660.1693 | D26: =C26*B26 -> 147164.4
A27: =IFERROR(__xludf.DUMMYFUNCTION("""COMPUTED_VALUE"""),"PEPSI ") -> PEPSI | B27: =IFERROR(__xludf.DUMMYFUNCTION("""COMPUTED_VALUE"""),204) -> 204 | C27: =IFERROR(__xludf.DUMMYFUNCTION("INDEX(RECETAS!E:E, MAX(FILTER(ROW(RECETAS!A:A), RECETAS!A:A=A27)) + 1)"),770.53) -> 770.53 | D27: =C27*B27 -> 157188.12
A28: =IFERROR(__xludf.DUMMYFUNCTION("""COMPUTED_VALUE"""),"PEPSI BLACK") -> PEPSI BLACK | B28: =IFERROR(__xludf.DUMMYFUNCTION("""COMPUTED_VALUE"""),43) -> 43 | C28: =IFERROR(__xludf.DUMMYFUNCTION("INDEX(RECETAS!E:E, MAX(FILTER(ROW(RECETAS!A:A), RECETAS!A:A=A28)) + 1)"),758.1) -> 758.1 | D28: =C28*B28 -> 32598.3
A29: =IFERROR(__xludf.DUMMYFUNCTION("""COMPUTED_VALUE"""),"PINTA DE CERVEZA") -> PINTA DE CERVEZA | B29: =IFERROR(__xludf.DUMMYFUNCTION("""COMPUTED_VALUE"""),2) -> 2 | C29: =IFERROR(__xludf.DUMMYFUNCTION("INDEX(RECETAS!E:E, MAX(FILTER(ROW(RECETAS!A:A), RECETAS!A:A=A29)) + 1)"),1899.93933333333) -> 1899.9393 | D29: =C29*B29 -> 3799.8787
A30: =IFERROR(__xludf.DUMMYFUNCTION("""COMPUTED_VALUE"""),"PORCION DE PAPAS") -> PORCION DE PAPAS | B30: =IFERROR(__xludf.DUMMYFUNCTION("""COMPUTED_VALUE"""),19) -> 19 | C30: =IFERROR(__xludf.DUMMYFUNCTION("INDEX(RECETAS!E:E, MAX(FILTER(ROW(RECETAS!A:A), RECETAS!A:A=A30)) + 1)"),2292.92034615384) -> 2292.9203 | D30: =C30*B30 -> 43565.487
A31: =IFERROR(__xludf.DUMMYFUNCTION("""COMPUTED_VALUE"""),"PORCION DE PAPAS CON CHEDDAR Y BACON") -> PORCION DE PAPAS CON CHEDDAR Y BACON | B31: =IFERROR(__xludf.DUMMYFUNCTION("""COMPUTED_VALUE"""),6) -> 6 | C31: =IFERROR(__xludf.DUMMYFUNCTION("INDEX(RECETAS!E:E, MAX(FILTER(ROW(RECETAS!A:A), RECETAS!A:A=A31)) + 1)"),3229.7962032967) -> 3229.7962 | D31: =C31*B31 -> 19378.777
A32: =IFERROR(__xludf.DUMMYFUNCTION("""COMPUTED_VALUE"""),"PORCION DE PAPAS Y CHEDDAR") -> PORCION DE PAPAS Y CHEDDAR | B32: =IFERROR(__xludf.DUMMYFUNCTION("""COMPUTED_VALUE"""),7) -> 7 | C32: =IFERROR(__xludf.DUMMYFUNCTION("INDEX(RECETAS!E:E, MAX(FILTER(ROW(RECETAS!A:A), RECETAS!A:A=A32)) + 1)"),2948.1332032967) -> 2948.1332 | D32: =C32*B32 -> 20636.932
A33: =IFERROR(__xludf.DUMMYFUNCTION("""COMPUTED_VALUE"""),"POSTRE CHOCOTORTA") -> POSTRE CHOCOTORTA | B33: =IFERROR(__xludf.DUMMYFUNCTION("""COMPUTED_VALUE"""),13) -> 13 | C33: =IFERROR(__xludf.DUMMYFUNCTION("INDEX(RECETAS!E:E, MAX(FILTER(ROW(RECETAS!A:A), RECETAS!A:A=A33)) + 1)"),2800) -> 2800 | D33: =C33*B33 -> 36400
A34: =IFERROR(__xludf.DUMMYFUNCTION("""COMPUTED_VALUE"""),"POSTRE OREO") -> POSTRE OREO | B34: =IFERROR(__xludf.DUMMYFUNCTION("""COMPUTED_VALUE"""),12) -> 12 | C34: =IFERROR(__xludf.DUMMYFUNCTION("INDEX(RECETAS!E:E, MAX(FILTER(ROW(RECETAS!A:A), RECETAS!A:A=A34)) + 1)"),2800) -> 2800 | D34: =C34*B34 -> 33600
A35: =IFERROR(__xludf.DUMMYFUNCTION("""COMPUTED_VALUE"""),"PULLED PORK") -> PULLED PORK | B35: =IFERROR(__xludf.DUMMYFUNCTION("""COMPUTED_VALUE"""),63) -> 63 | C35: =IFERROR(__xludf.DUMMYFUNCTION("INDEX(RECETAS!E:E, MAX(FILTER(ROW(RECETAS!A:A), RECETAS!A:A=A35)) + 1)"),2652.60312106293) -> 2652.6031 | D35: =C35*B35 -> 167114
A36: =IFERROR(__xludf.DUMMYFUNCTION("""COMPUTED_VALUE"""),"SEVEN-UP") -> SEVEN-UP | B36: =IFERROR(__xludf.DUMMYFUNCTION("""COMPUTED_VALUE"""),126) -> 126 | C36: =IFERROR(__xludf.DUMMYFUNCTION("INDEX(RECETAS!E:E, MAX(FILTER(ROW(RECETAS!A:A), RECETAS!A:A=A36)) + 1)"),758.113333333333) -> 758.11333 | D36: =C36*B36 -> 95522.28
A37: =IFERROR(__xludf.DUMMYFUNCTION("""COMPUTED_VALUE"""),"SWEET BACON BURGER") -> SWEET BACON BURGER | B37: =IFERROR(__xludf.DUMMYFUNCTION("""COMPUTED_VALUE"""),31) -> 31 | C37: =IFERROR(__xludf.DUMMYFUNCTION("INDEX(RECETAS!E:E, MAX(FILTER(ROW(RECETAS!A:A), RECETAS!A:A=A37)) + 1)"),5148.53157939627) -> 5148.5316 | D37: =C37*B37 -> 159604.48
A38: =IFERROR(__xludf.DUMMYFUNCTION("""COMPUTED_VALUE"""),"SWEET ONION") -> SWEET ONION | B38: =IFERROR(__xludf.DUMMYFUNCTION("""COMPUTED_VALUE"""),68) -> 68 | C38: =IFERROR(__xludf.DUMMYFUNCTION("INDEX(RECETAS!E:E, MAX(FILTER(ROW(RECETAS!A:A), RECETAS!A:A=A38)) + 1)"),5183.03047939627) -> 5183.0305 | D38: =C38*B38 -> 352446.07
A39: =IFERROR(__xludf.DUMMYFUNCTION("""COMPUTED_VALUE"""),"TASTY WLB") -> TASTY WLB | B39: =IFERROR(__xludf.DUMMYFUNCTION("""COMPUTED_VALUE"""),41) -> 41 | C39: =IFERROR(__xludf.DUMMYFUNCTION("INDEX(RECETAS!E:E, MAX(FILTER(ROW(RECETAS!A:A), RECETAS!A:A=A39)) + 1)"),5411.03157939627) -> 5411.0316 | D39: =C39*B39 -> 221852.29
A40: =IFERROR(__xludf.DUMMYFUNCTION("""COMPUTED_VALUE"""),"TRIPLE CHEESE BACON") -> TRIPLE CHEESE BACON | B40: =IFERROR(__xludf.DUMMYFUNCTION("""COMPUTED_VALUE"""),64) -> 64 | C40: =IFERROR(__xludf.DUMMYFUNCTION("INDEX(RECETAS!E:E, MAX(FILTER(ROW(RECETAS!A:A), RECETAS!A:A=A40)) + 1)"),6830.32040995182) -> 6830.3204 | D40: =C40*B40 -> 437140.51
A41: =IFERROR(__xludf.DUMMYFUNCTION("""COMPUTED_VALUE"""),"VEGGIE BURGER") -> VEGGIE BURGER | B41: =IFERROR(__xludf.DUMMYFUNCTION("""COMPUTED_VALUE"""),26) -> 26 | C41: =IFERROR(__xludf.DUMMYFUNCTION("INDEX(RECETAS!E:E, MAX(FILTER(ROW(RECETAS!A:A), RECETAS!A:A=A41)) + 1)"),2674.4117877296) -> 2674.4118 | D41: =C41*B41 -> 69534.706
...

Sheet CMV TOTAL 02-2026
A1: PRODUCTOS | B1: TOTAL | C1: COSTO UNITARIO | D1: COSTO TOTAL | E1: CMV | F1: CMV
A3: =IFERROR(__xludf.DUMMYFUNCTION("QUERY(ResumenVentas!A:B, ""Select A, sum(B) where A is not null group by A label sum(B) 'TOTAL'"", 1)"),"Producto") -> Producto | B3: =IFERROR(__xludf.DUMMYFUNCTION("""COMPUTED_VALUE"""),"TOTAL") -> TOTAL
A4: =IFERROR(__xludf.DUMMYFUNCTION("""COMPUTED_VALUE"""),"AGUA MANZANA H20") -> AGUA MANZANA H20 | B4: =IFERROR(__xludf.DUMMYFUNCTION("""COMPUTED_VALUE"""),9) -> 9 | C4: =IFERROR(__xludf.DUMMYFUNCTION("INDEX(RECETAS!E:E, MAX(FILTER(ROW(RECETAS!A:A), RECETAS!A:A=A4)) + 1)"),717.358333333333) -> 717.35833 | D4: =C4*B4 -> 6456.225 | E4: =#REF! -> #REF! | F4: =#REF! -> #REF!
A5: =IFERROR(__xludf.DUMMYFUNCTION("""COMPUTED_VALUE"""),"AGUA MINERAL") -> AGUA MINERAL | B5: =IFERROR(__xludf.DUMMYFUNCTION("""COMPUTED_VALUE"""),45) -> 45 | C5: =IFERROR(__xludf.DUMMYFUNCTION("INDEX(RECETAS!E:E, MAX(FILTER(ROW(RECETAS!A:A), RECETAS!A:A=A5)) + 1)"),920.664166666666) -> 920.66417 | D5: =C5*B5 -> 41429.887
A6: =IFERROR(__xludf.DUMMYFUNCTION("""COMPUTED_VALUE"""),"AGUA POMELO H20") -> AGUA POMELO H20 | B6: =IFERROR(__xludf.DUMMYFUNCTION("""COMPUTED_VALUE"""),40) -> 40 | C6: =IFERROR(__xludf.DUMMYFUNCTION("INDEX(RECETAS!E:E, MAX(FILTER(ROW(RECETAS!A:A), RECETAS!A:A=A6)) + 1)"),717.375) -> 717.375 | D6: =C6*B6 -> 28695
A7: =IFERROR(__xludf.DUMMYFUNCTION("""COMPUTED_VALUE"""),"AMERICAN BURGER") -> AMERICAN BURGER | B7: =IFERROR(__xludf.DUMMYFUNCTION("""COMPUTED_VALUE"""),87) -> 87 | C7: =IFERROR(__xludf.DUMMYFUNCTION("INDEX(RECETAS!E:E, MAX(FILTER(ROW(RECETAS!A:A), RECETAS!A:A=A7)) + 1)"),5886.03157939627) -> 5886.0316 | D7: =C7*B7 -> 512084.75
A8: =IFERROR(__xludf.DUMMYFUNCTION("""COMPUTED_VALUE"""),"AROS DE CEBOLLA") -> AROS DE CEBOLLA | B8: =IFERROR(__xludf.DUMMYFUNCTION("""COMPUTED_VALUE"""),7) -> 7 | C8: =IFERROR(__xludf.DUMMYFUNCTION("INDEX(RECETAS!E:E, MAX(FILTER(ROW(RECETAS!A:A), RECETAS!A:A=A8)) + 1)"),2027.49327948717) -> 2027.4933 | D8: =C8*B8 -> 14192.453
A9: =IFERROR(__xludf.DUMMYFUNCTION("""COMPUTED_VALUE"""),"BLUE CHEESE") -> BLUE CHEESE | B9: =IFERROR(__xludf.DUMMYFUNCTION("""COMPUTED_VALUE"""),35) -> 35 | C9: =IFERROR(__xludf.DUMMYFUNCTION("INDEX(RECETAS!E:E, MAX(FILTER(ROW(RECETAS!A:A), RECETAS!A:A=A9)) + 1)"),5298.53157939627) -> 5298.5316 | D9: =C9*B9 -> 185448.61
A10: =IFERROR(__xludf.DUMMYFUNCTION("""COMPUTED_VALUE"""),"BOTELLA DE CERVEZA") -> BOTELLA DE CERVEZA | B10: =IFERROR(__xludf.DUMMYFUNCTION("""COMPUTED_VALUE"""),11) -> 11 | C10: =IFERROR(__xludf.DUMMYFUNCTION("INDEX(RECETAS!E:E, MAX(FILTER(ROW(RECETAS!A:A), RECETAS!A:A=A10)) + 1)"),1899.93933333333) -> 1899.9393 | D10: =C10*B10 -> 20899.333
A11: =IFERROR(__xludf.DUMMYFUNCTION("""COMPUTED_VALUE"""),"CHEESE BACON") -> CHEESE BACON | B11: =IFERROR(__xludf.DUMMYFUNCTION("""COMPUTED_VALUE"""),172) -> 172 | C11: =IFERROR(__xludf.DUMMYFUNCTION("INDEX(RECETAS!E:E, MAX(FILTER(ROW(RECETAS!A:A), RECETAS!A:A=A11)) + 1)"),5183.03047939627) -> 5183.0305 | D11: =C11*B11 -> 891481.24
A12: =IFERROR(__xludf.DUMMYFUNCTION("""COMPUTED_VALUE"""),"CHEESE BURGER") -> CHEESE BURGER | B12: =IFERROR(__xludf.DUMMYFUNCTION("""COMPUTED_VALUE"""),3) -> 3 | C12: =IFERROR(__xludf.DUMMYFUNCTION("INDEX(RECETAS!E:E, MAX(FILTER(ROW(RECETAS!A:A), RECETAS!A:A=A12)) + 1)"),5073.90657939627) -> 5073.9066 | D12: =C12*B12 -> 15221.72
A13: =IFERROR(__xludf.DUMMYFUNCTION("""COMPUTED_VALUE"""),"CHEESE BURGER CANJE") -> CHEESE BURGER CANJE | B13: =IFERROR(__xludf.DUMMYFUNCTION("""COMPUTED_VALUE"""),8) -> 8 | C13: =IFERROR(__xludf.DUMMYFUNCTION("INDEX(RECETAS!E:E, MAX(FILTER(ROW(RECETAS!A:A), RECETAS!A:A=A13)) + 1)"),2086.06704059829) -> 2086.067 | D13: =C13*B13 -> 16688.536
A14: =IFERROR(__xludf.DUMMYFUNCTION("""COMPUTED_VALUE"""),"CRISPY BURGER") -> CRISPY BURGER | B14: =IFERROR(__xludf.DUMMYFUNCTION("""COMPUTED_VALUE"""),51) -> 51 | C14: =IFERROR(__xludf.DUMMYFUNCTION("INDEX(RECETAS!E:E, MAX(FILTER(ROW(RECETAS!A:A), RECETAS!A:A=A14)) + 1)"),5233.03047939627) -> 5233.0305 | D14: =C14*B14 -> 266884.55
A15: =IFERROR(__xludf.DUMMYFUNCTION("""COMPUTED_VALUE"""),"DOBLE CUARTO") -> DOBLE CUARTO | B15: =IFERROR(__xludf.DUMMYFUNCTION("""COMPUTED_VALUE"""),50) -> 50 | C15: =IFERROR(__xludf.DUMMYFUNCTION("INDEX(RECETAS!E:E, MAX(FILTER(ROW(RECETAS!A:A), RECETAS!A:A=A15)) + 1)"),5326.66684303263) -> 5326.6668 | D15: =C15*B15 -> 266333.34
A16: =IFERROR(__xludf.DUMMYFUNCTION("""COMPUTED_VALUE"""),"EXTRA MEDALLON") -> EXTRA MEDALLON | B16: =IFERROR(__xludf.DUMMYFUNCTION("""COMPUTED_VALUE"""),3) -> 3 | C16: =IFERROR(__xludf.DUMMYFUNCTION("INDEX(RECETAS!E:E, MAX(FILTER(ROW(RECETAS!A:A), RECETAS!A:A=A16)) + 1)"),1421.75) -> 1421.75 | D16: =C16*B16 -> 4265.25
A17: =IFERROR(__xludf.DUMMYFUNCTION("""COMPUTED_VALUE"""),"HUMPTY BURGER") -> HUMPTY BURGER | B17: =IFERROR(__xludf.DUMMYFUNCTION("""COMPUTED_VALUE"""),74) -> 74 | C17: =IFERROR(__xludf.DUMMYFUNCTION("INDEX(RECETAS!E:E, MAX(FILTER(ROW(RECETAS!A:A), RECETAS!A:A=A17)) + 1)"),5409.69714606293) -> 5409.6971 | D17: =C17*B17 -> 400317.59
A18: =IFERROR(__xludf.DUMMYFUNCTION("""COMPUTED_VALUE"""),"JIMMY BURGER") -> JIMMY BURGER | B18: =IFERROR(__xludf.DUMMYFUNCTION("""COMPUTED_VALUE"""),34) -> 34 | C18: =IFERROR(__xludf.DUMMYFUNCTION("INDEX(RECETAS!E:E, MAX(FILTER(ROW(RECETAS!A:A), RECETAS!A:A=A18)) + 1)"),3923.49054884071) -> 3923.4905 | D18: =C18*B18 -> 133398.68
A19: =IFERROR(__xludf.DUMMYFUNCTION("""COMPUTED_VALUE"""),"MEDALLON VEGGIE") -> MEDALLON VEGGIE | B19: =IFERROR(__xludf.DUMMYFUNCTION("""COMPUTED_VALUE"""),1) -> 1 | C19: =IFERROR(__xludf.DUMMYFUNCTION("INDEX(RECETAS!E:E, MAX(FILTER(ROW(RECETAS!A:A), RECETAS!A:A=A19)) + 1)"),700) -> 700 | D19: =C19*B19 -> 700
A20: =IFERROR(__xludf.DUMMYFUNCTION("""COMPUTED_VALUE"""),"MEDIA PINTA DE CERVEZA") -> MEDIA PINTA DE CERVEZA | B20: =IFERROR(__xludf.DUMMYFUNCTION("""COMPUTED_VALUE"""),64) -> 64 | C20: =IFERROR(__xludf.DUMMYFUNCTION("INDEX(RECETAS!E:E, MAX(FILTER(ROW(RECETAS!A:A), RECETAS!A:A=A20)) + 1)"),949.969666666666) -> 949.96967 | D20: =C20*B20 -> 60798.059
A21: =IFERROR(__xludf.DUMMYFUNCTION("""COMPUTED_VALUE"""),"MIGI BURGER") -> MIGI BURGER | B21: =IFERROR(__xludf.DUMMYFUNCTION("""COMPUTED_VALUE"""),164) -> 164 | C21: =IFERROR(__xludf.DUMMYFUNCTION("INDEX(RECETAS!E:E, MAX(FILTER(ROW(RECETAS!A:A), RECETAS!A:A=A21)) + 1)"),4209.03157939627) -> 4209.0316 | D21: =C21*B21 -> 690281.18
A22: =IFERROR(__xludf.DUMMYFUNCTION("""COMPUTED_VALUE"""),"MIRINDA") -> MIRINDA | B22: =IFERROR(__xludf.DUMMYFUNCTION("""COMPUTED_VALUE"""),36) -> 36 | C22: =IFERROR(__xludf.DUMMYFUNCTION("INDEX(RECETAS!E:E, MAX(FILTER(ROW(RECETAS!A:A), RECETAS!A:A=A22)) + 1)"),758.113333333333) -> 758.11333 | D22: =C22*B22 -> 27292.08
A23: =IFERROR(__xludf.DUMMYFUNCTION("""COMPUTED_VALUE"""),"MOBY DICK") -> MOBY DICK | B23: =IFERROR(__xludf.DUMMYFUNCTION("""COMPUTED_VALUE"""),70) -> 70 | C23: =IFERROR(__xludf.DUMMYFUNCTION("INDEX(RECETAS!E:E, MAX(FILTER(ROW(RECETAS!A:A), RECETAS!A:A=A23)) + 1)"),8562.10924050738) -> 8562.1092 | D23: =C23*B23 -> 599347.65
A24: =IFERROR(__xludf.DUMMYFUNCTION("""COMPUTED_VALUE"""),"NUGGETS X 10") -> NUGGETS X 10 | B24: =IFERROR(__xludf.DUMMYFUNCTION("""COMPUTED_VALUE"""),12) -> 12 | C24: =IFERROR(__xludf.DUMMYFUNCTION("INDEX(RECETAS!E:E, MAX(FILTER(ROW(RECETAS!A:A), RECETAS!A:A=A24)) + 1)"),2756.21051282051) -> 2756.2105 | D24: =C24*B24 -> 33074.526
A25: =IFERROR(__xludf.DUMMYFUNCTION("""COMPUTED_VALUE"""),"NUGGETS X 6") -> NUGGETS X 6 | B25: =IFERROR(__xludf.DUMMYFUNCTION("""COMPUTED_VALUE"""),5) -> 5 | C25: =IFERROR(__xludf.DUMMYFUNCTION("INDEX(RECETAS!E:E, MAX(FILTER(ROW(RECETAS!A:A), RECETAS!A:A=A25)) + 1)"),1680.52117948717) -> 1680.5212 | D25: =C25*B25 -> 8402.6059
A26: =IFERROR(__xludf.DUMMYFUNCTION("""COMPUTED_VALUE"""),"ONION RINGS BURGER") -> ONION RINGS BURGER | B26: =IFERROR(__xludf.DUMMYFUNCTION("""COMPUTED_VALUE"""),26) -> 26 | C26: =IFERROR(__xludf.DUMMYFUNCTION("INDEX(RECETAS!E:E, MAX(FILTER(ROW(RECETAS!A:A), RECETAS!A:A=A26)) + 1)"),5660.1693127296) -> 5660.1693 | D26: =C26*B26 -> 147164.4
A27: =IFERROR(__xludf.DUMMYFUNCTION("""COMPUTED_VALUE"""),"PEPSI ") -> PEPSI | B27: =IFERROR(__xludf.DUMMYFUNCTION("""COMPUTED_VALUE"""),204) -> 204 | C27: =IFERROR(__xludf.DUMMYFUNCTION("INDEX(RECETAS!E:E, MAX(FILTER(ROW(RECETAS!A:A), RECETAS!A:A=A27)) + 1)"),770.53) -> 770.53 | D27: =C27*B27 -> 157188.12
A28: =IFERROR(__xludf.DUMMYFUNCTION("""COMPUTED_VALUE"""),"PEPSI BLACK") -> PEPSI BLACK | B28: =IFERROR(__xludf.DUMMYFUNCTION("""COMPUTED_VALUE"""),43) -> 43 | C28: =IFERROR(__xludf.DUMMYFUNCTION("INDEX(RECETAS!E:E, MAX(FILTER(ROW(RECETAS!A:A), RECETAS!A:A=A28)) + 1)"),758.1) -> 758.1 | D28: =C28*B28 -> 32598.3
A29: =IFERROR(__xludf.DUMMYFUNCTION("""COMPUTED_VALUE"""),"PINTA DE CERVEZA") -> PINTA DE CERVEZA | B29: =IFERROR(__xludf.DUMMYFUNCTION("""COMPUTED_VALUE"""),2) -> 2 | C29: =IFERROR(__xludf.DUMMYFUNCTION("INDEX(RECETAS!E:E, MAX(FILTER(ROW(RECETAS!A:A), RECETAS!A:A=A29)) + 1)"),1899.93933333333) -> 1899.9393 | D29: =C29*B29 -> 3799.8787
A30: =IFERROR(__xludf.DUMMYFUNCTION("""COMPUTED_VALUE"""),"PORCION DE PAPAS") -> PORCION DE PAPAS | B30: =IFERROR(__xludf.DUMMYFUNCTION("""COMPUTED_VALUE"""),19) -> 19 | C30: =IFERROR(__xludf.DUMMYFUNCTION("INDEX(RECETAS!E:E, MAX(FILTER(ROW(RECETAS!A:A), RECETAS!A:A=A30)) + 1)"),2292.92034615384) -> 2292.9203 | D30: =C30*B30 -> 43565.487
A31: =IFERROR(__xludf.DUMMYFUNCTION("""COMPUTED_VALUE"""),"PORCION DE PAPAS CON CHEDDAR Y BACON") -> PORCION DE PAPAS CON CHEDDAR Y BACON | B31: =IFERROR(__xludf.DUMMYFUNCTION("""COMPUTED_VALUE"""),6) -> 6 | C31: =IFERROR(__xludf.DUMMYFUNCTION("INDEX(RECETAS!E:E, MAX(FILTER(ROW(RECETAS!A:A), RECETAS!A:A=A31)) + 1)"),3229.7962032967) -> 3229.7962 | D31: =C31*B31 -> 19378.777
A32: =IFERROR(__xludf.DUMMYFUNCTION("""COMPUTED_VALUE"""),"PORCION DE PAPAS Y CHEDDAR") -> PORCION DE PAPAS Y CHEDDAR | B32: =IFERROR(__xludf.DUMMYFUNCTION("""COMPUTED_VALUE"""),7) -> 7 | C32: =IFERROR(__xludf.DUMMYFUNCTION("INDEX(RECETAS!E:E, MAX(FILTER(ROW(RECETAS!A:A), RECETAS!A:A=A32)) + 1)"),2948.1332032967) -> 2948.1332 | D32: =C32*B32 -> 20636.932
A33: =IFERROR(__xludf.DUMMYFUNCTION("""COMPUTED_VALUE"""),"POSTRE CHOCOTORTA") -> POSTRE CHOCOTORTA | B33: =IFERROR(__xludf.DUMMYFUNCTION("""COMPUTED_VALUE"""),13) -> 13 | C33: =IFERROR(__xludf.DUMMYFUNCTION("INDEX(RECETAS!E:E, MAX(FILTER(ROW(RECETAS!A:A), RECETAS!A:A=A33)) + 1)"),2800) -> 2800 | D33: =C33*B33 -> 36400
A34: =IFERROR(__xludf.DUMMYFUNCTION("""COMPUTED_VALUE"""),"POSTRE OREO") -> POSTRE OREO | B34: =IFERROR(__xludf.DUMMYFUNCTION("""COMPUTED_VALUE"""),12) -> 12 | C34: =IFERROR(__xludf.DUMMYFUNCTION("INDEX(RECETAS!E:E, MAX(FILTER(ROW(RECETAS!A:A), RECETAS!A:A=A34)) + 1)"),2800) -> 2800 | D34: =C34*B34 -> 33600
A35: =IFERROR(__xludf.DUMMYFUNCTION("""COMPUTED_VALUE"""),"PULLED PORK") -> PULLED PORK | B35: =IFERROR(__xludf.DUMMYFUNCTION("""COMPUTED_VALUE"""),63) -> 63 | C35: =IFERROR(__xludf.DUMMYFUNCTION("INDEX(RECETAS!E:E, MAX(FILTER(ROW(RECETAS!A:A), RECETAS!A:A=A35)) + 1)"),2652.60312106293) -> 2652.6031 | D35: =C35*B35 -> 167114
A36: =IFERROR(__xludf.DUMMYFUNCTION("""COMPUTED_VALUE"""),"SEVEN-UP") -> SEVEN-UP | B36: =IFERROR(__xludf.DUMMYFUNCTION("""COMPUTED_VALUE"""),126) -> 126 | C36: =IFERROR(__xludf.DUMMYFUNCTION("INDEX(RECETAS!E:E, MAX(FILTER(ROW(RECETAS!A:A), RECETAS!A:A=A36)) + 1)"),758.113333333333) -> 758.11333 | D36: =C36*B36 -> 95522.28
A37: =IFERROR(__xludf.DUMMYFUNCTION("""COMPUTED_VALUE"""),"SWEET BACON BURGER") -> SWEET BACON BURGER | B37: =IFERROR(__xludf.DUMMYFUNCTION("""COMPUTED_VALUE"""),31) -> 31 | C37: =IFERROR(__xludf.DUMMYFUNCTION("INDEX(RECETAS!E:E, MAX(FILTER(ROW(RECETAS!A:A), RECETAS!A:A=A37)) + 1)"),5148.53157939627) -> 5148.5316 | D37: =C37*B37 -> 159604.48
A38: =IFERROR(__xludf.DUMMYFUNCTION("""COMPUTED_VALUE"""),"SWEET ONION") -> SWEET ONION | B38: =IFERROR(__xludf.DUMMYFUNCTION("""COMPUTED_VALUE"""),68) -> 68 | C38: =IFERROR(__xludf.DUMMYFUNCTION("INDEX(RECETAS!E:E, MAX(FILTER(ROW(RECETAS!A:A), RECETAS!A:A=A38)) + 1)"),5183.03047939627) -> 5183.0305 | D38: =C38*B38 -> 352446.07
A39: =IFERROR(__xludf.DUMMYFUNCTION("""COMPUTED_VALUE"""),"TASTY WLB") -> TASTY WLB | B39: =IFERROR(__xludf.DUMMYFUNCTION("""COMPUTED_VALUE"""),41) -> 41 | C39: =IFERROR(__xludf.DUMMYFUNCTION("INDEX(RECETAS!E:E, MAX(FILTER(ROW(RECETAS!A:A), RECETAS!A:A=A39)) + 1)"),5411.03157939627) -> 5411.0316 | D39: =C39*B39 -> 221852.29
A40: =IFERROR(__xludf.DUMMYFUNCTION("""COMPUTED_VALUE"""),"TRIPLE CHEESE BACON") -> TRIPLE CHEESE BACON | B40: =IFERROR(__xludf.DUMMYFUNCTION("""COMPUTED_VALUE"""),64) -> 64 | C40: =IFERROR(__xludf.DUMMYFUNCTION("INDEX(RECETAS!E:E, MAX(FILTER(ROW(RECETAS!A:A), RECETAS!A:A=A40)) + 1)"),6830.32040995182) -> 6830.3204 | D40: =C40*B40 -> 437140.51
A41: =IFERROR(__xludf.DUMMYFUNCTION("""COMPUTED_VALUE"""),"VEGGIE BURGER") -> VEGGIE BURGER | B41: =IFERROR(__xludf.DUMMYFUNCTION("""COMPUTED_VALUE"""),26) -> 26 | C41: =IFERROR(__xludf.DUMMYFUNCTION("INDEX(RECETAS!E:E, MAX(FILTER(ROW(RECETAS!A:A), RECETAS!A:A=A41)) + 1)"),2674.4117877296) -> 2674.4118 | D41: =C41*B41 -> 69534.706
...

Sheet ResumenVentas
A1: Producto | B1: Cantidad
A2: MOBY DICK | B2: 1
A3: AMERICAN BURGER | B3: 1
A4: PEPSI | B4: 1
A5: CHEESE BACON | B5: 1
A6: MOBY DICK | B6: 1
A7: SEVEN-UP | B7: 1
A8: PEPSI | B8: 1
A9: HUMPTY BURGER | B9: 1
A10: PEPSI | B10: 1
A11: AMERICAN BURGER | B11: 1
A12: AMERICAN BURGER | B12: 1
A13: EXTRA MEDALLON | B13: -1
... A119: SEVEN-UP | B119: 1
A120: SEVEN-UP
